Workbook

Sheet 说明
A1: 埃尔德《以交易为生》选股评分模型(第一步:Excel 公式版)
A3: 用途 | B3: 把书中的三重滤网、动力系统、价值区间/通道、MACD柱背离+假突破、强力指数、ATR、2%/6%风险法则全部落成公式,对一只股票的日线数据打分、给出次日挂单价/止损/目标/股数。
A4: 色彩约定 | B4: 浅黄色=可输入/可改的单元格;浅蓝色=公式输出;深蓝表头=公式列。
A5: 工作表 | B5: 参数 → 日线(粘贴OHLCV,指标全自动)→ 周线(自动汇总)→ 评分卡(看结论)→ 仓位与风险(2%/6%)→ 交易评级 → 市场温度 → 图表。
A6: 使用步骤 | B6: ① 在"日线"A:F 列粘贴自己的日期/开/高/低/收/量(示例为合成数据)。② 必要时在"参数"调通道系数(使近100根K线约95%落在通道内)。③ 在"市场温度"填大盘4个读数。④ 打开"评分卡"看总分、否决项、挂单计划。⑤ 买入后在"仓位与风险"登记,监控6%额度。⑥ 平仓后在"交易评级"打分复盘。
A7: 扩展数据 | B7: 行数不够时:选中日线最后一行的公式列(G列起)向下填充即可;周线预留80周。批量处理几千只股票请使用第三步的 Python 引擎(与本表同一套定义,已逐行对账)。
A8: 信号定义 | B8: 动力系统:EMA快↑且MACD柱↑=绿(禁止卖空);EMA快↓且柱↓=红(禁止买入);否则蓝。形态A:周EMA慢向上、日线非红、2日强力指数<0且非数周新低、收盘≤EMA快且≥通道下轨。形态B:MACD柱两个负区段谷底,价格更低而柱谷更浅、间隔在参数范围内、柱线回升。形态C:价格低于通道下轨且2日强力指数深度超过平均负值的5倍后回升。
A9: 买入价 | B9: 三重滤网第三重:明日EMA估计 − 平均下跌穿透,即在回调中以折价挂单,不追高。
A10: 止损 | B10: 尼克止损:近期次低点下方1分,且至少离买入价 N×ATR,并避开整数/半整数价位,以免落入拥挤的止损单区域。
A11: 目标 | B11: 上通道线(书:在价值区间买入、通道上轨附近兑现)。分批:1/3在+1ATR,1/3在+2ATR,其余在+3ATR或动力系统转蓝/红时离场。
A12: 风险 | B12: 单笔风险=资金×风险%(默认1%,上限2%);月度已亏损+持仓风险≥6%停止开新仓;止损上移到保本即释放额度。
A13: 免责声明 | B13: 示例数据为合成数据。权重、阈值、大盘系数为本方案设计假设,尚未经真实历史回测验证;模型仅作研究与教育用途,不构成投资建议。

Sheet 参数
A1: 参数表(浅黄色单元格可修改,全部公式引用此表)
A3: 名称(定义名) | B3: 含义 | C3: 取值 | D3: 来源 / 依据
A4: 趋势与价值区间
A5: p_EmaF | B5: 快速EMA周期(价值区间上沿) | C5: 13 | D5: 第22节:与慢线保持约 2:1(13/26)
A6: p_EmaS | B6: 慢速EMA周期(趋势线/价值区间下沿) | C6: 26 | D6: 第22节:26≈半年周数,22≈月交易日
A7: p_MacdF | B7: MACD 快线周期 | C7: 12 | D7: 第23节(12-26-9)
A8: p_MacdS | B8: MACD 慢线周期 | C8: 26 | D8: 第23节
A9: p_MacdSig | B9: MACD 信号线周期 | C9: 9 | D9: 第23节
A10: p_AdxN | B10: 趋向系统(ADX)平滑周期 | C10: 13 | D10: 第24节(13)
A11: 波动率、通道、止损
A12: p_AtrN | B12: ATR 平均天数 | C12: 13 | D12: 第24节(13日)
A13: p_ChPct | B13: 通道系数(占慢EMA比例) | C13: 0.06 | D13: 第22/41节:调到覆盖近100根K线约95%;A股日线建议先用6%,按个股校准
A14: p_PenLb | B14: 平均下跌穿透回溯期(根) | C14: 30 | D14: 第39节:回看4-6周日线
A15: p_StopLb | B15: 尼克止损回溯期(根) | C15: 10 | D15: 第54节:近期次低点
A16: p_StopAtr | B16: 止损距入场最少 ATR 倍数 | C16: 1 | D16: 第24/54节:至少1倍ATR,2倍更稳
A17: 震荡指标
A18: p_FiS | B18: 强力指数短周期 | C18: 2 | D18: 第30节(2日EMA,择时)
A19: p_FiL | B19: 强力指数长周期 | C19: 13 | D19: 第30节(13日EMA,趋势)
A20: p_FiLb | B20: 强力指数"几周内新低"回溯期(根) | C20: 20 | D20: 第39节:2日FI不能创数周新低
A21: p_StochN | B21: 随机指标周期 | C21: 5 | D21: 第26节(5)
A22: p_StochSm | B22: 随机指标平滑 | C22: 3 | D22: 第26节(3)
A23: 背离识别
A24: p_GapMin | B24: 背离两谷最小间隔(根) | C24: 10 | D24: 第23节:20-40根最佳;此处放宽为10-60
A25: p_GapMax | B25: 背离两谷最大间隔(根) | C25: 60 | D25: 同上
A26: 评级与风险
A27: p_RRmin | B27: 最小盈亏比 | C27: 2 | D27: 第38/53节:至少2:1
A28: p_GradeA | B28: A级评分阈值 | C28: 70 | D28: 设计假设,待第三步回测校准
A29: p_GradeB | B29: B级评分阈值 | C29: 55 | D29: 设计假设,待第三步回测校准
A30: p_Equity | B30: 交易账户资金(元) | C30: 1000000 | D30: 第50节:仅指交易账户,不含储蓄/退休金
A31: p_RiskTrade | B31: 单笔风险比例(默认1%) | C31: 0.01 | D31: 第50节:专业人士常用≤1%
A32: p_RiskCap | B32: 单笔风险上限(2%法则) | C32: 0.02 | D32: 第50节:绝对上限2%
A33: p_RiskMonth | B33: 月度总风险上限(6%法则) | C33: 0.06 | D33: 第51节:已亏损+持仓风险≥6%停止开新仓
A34: p_PosCap | B34: 单只股票最大仓位占比 | C34: 0.2 | D34: 设计假设:A股T+1、涨跌停缺口会放大实际亏损,限制集中度
A35: p_Lot | B35: 最小交易单位(股) | C35: 100 | D35: A股:100股/手

Sheet 评分卡
A1: 评分卡 —— 单只股票打分与次日挂单计划
A3: 标的 | B3: DEMO 示例股份(合成数据)
A4: 评分日期 | B4: =MAX(日线!$A$5:$A$310) -> 46086 | C4: 可改为历史任意交易日回看
A5: 行号(内部) | B5: =MATCH(B4,日线!$A$5:$A$310,0) -> 306
A7: 维度 | B7: 项目 | C7: 当前值 | D7: 规则 | E7: 得分 | F7: 满分
A8: ① 趋势(25) | B8: 上周 EMA慢是否向上 | C8: =INDEX(日线!$BS$5:$BS$310,$B$5) -> 1 | D8: 向上=10分(第一重滤网) | E8: =IF(C8=1,10,0) -> 10 | F8: 10
B9: 上周动力系统 | C9: =INDEX(日线!$BU$5:$BU$310,$B$5) -> 1 | D9: 绿=5 / 蓝=3 / 红=0(红色禁止买入) | E9: =IF(C9=1,5,IF(C9=-1,0,3)) -> 5 | F9: 5
B10: 上周 MACD 柱斜率向上 | C10: =INDEX(日线!$BT$5:$BT$310,$B$5) -> 1 | D10: 向上=5 | E10: =IF(C10=1,5,0) -> 5 | F10: 5
B11: ADX 上升且 +DI>-DI | C11: =IF(AND(INDEX(日线!$AE$5:$AE$310,$B$5)>INDEX(日线!$AF$5:$AF$310,$B$5),INDEX(日线!$AH$5:$AH$310,$B$5)>INDEX(日线!$AH$5:$AH$310,MAX(1,$B$5-1))),1,0) -> 0 | D11: 趋势有劲=5(第24节) | E11: =IF(C11=1,5,0) -> 0 | F11: 5
A12: ② 回调质量(25) | B12: 价格相对价值区间 | C12: =IF(AND(INDEX(日线!$E$5:$E$310,$B$5)<=INDEX(日线!$H$5:$H$310,$B$5),INDEX(日线!$E$5:$E$310,$B$5)>=INDEX(日线!$I$5:$I$310,$B$5)),"价值区间内",IF(AND(INDEX(日线!$E$5:$E$310,$B$5)>=INDEX(日线!$AJ$5:$AJ$310,$B$5),INDEX(日线!$E$5:$E$310,$B$5)<INDEX(日线!$I$5:$I$310,$B$5)),"慢EMA下方","区间外/追高")) -> 价值区间内 | D12: 区间内=10 / 慢线下方但在通道内=6 / 其他=0(不追高) | E12: =IF(C12="价值区间内",10,IF(C12="慢EMA下方",6,0)) -> 10 | F12: 10
B13: 2日强力指数<0 且非数周新低 | C13: =IF(AND(INDEX(日线!$V$5:$V$310,$B$5)<0,INDEX(日线!$BO$5:$BO$310,$B$5)=1),1,0) -> 1 | D13: 满足=8(第二重滤网) | E13: =IF(C13=1,8,0) -> 8 | F13: 8
B14: 慢速随机指标 %K | C14: =INDEX(日线!$AT$5:$AT$310,$B$5) -> 47.701149 | D14: <30=7 / <50=3 | E14: =IF(C14<30,7,IF(C14<50,3,0)) -> 3 | F14: 7
A15: ③ 买入形态(25) | B15: 形态A 回调到价值区(顺势) | C15: =INDEX(日线!$BV$5:$BV$310,$B$5) -> 1 | D15: 仅A=15
B16: 形态B MACD柱牛市背离/假突破 | C16: =INDEX(日线!$BW$5:$BW$310,$B$5) -> 0 | D16: 仅B=22,A+B=25
B17: 形态C 极端超卖反弹 | C17: =INDEX(日线!$BX$5:$BX$310,$B$5) -> 0 | D17: 仅C=12 | E17: =IF(AND(C15=1,C16=1),25,IF(C16=1,22,IF(C15=1,15,IF(C17=1,12,0)))) -> 15 | F17: 25
A18: ④ 量能(10) | B18: 13日强力指数>0 | C18: =IF(INDEX(日线!$W$5:$W$310,$B$5)>0,1,0) -> 0 | D18: 多头占优=6 | E18: =IF(C18=1,6,0) -> 0 | F18: 6
B19: 今日量<5日均量(缩量回调) | C19: =IF(INDEX(日线!$F$5:$F$310,$B$5)<INDEX(日线!$BR$5:$BR$310,$B$5),1,0) -> 0 | D19: 缩量=4 | E19: =IF(C19=1,4,0) -> 0 | F19: 4
A20: ⑤ 盈亏比(15) | B20: 盈亏比 (目标−买入)/(买入−止损) | C20: =INDEX(日线!$BC$5:$BC$310,$B$5) -> 3.2622951 | D20: ≥3=15 / ≥参数=10 / ≥1.5=4 | E20: =IF(C20>=3,15,IF(C20>=p_RRmin,10,IF(C20>=1.5,4,0))) -> 15 | F20: 15
A21: 总分 | E21: =SUM(E8:E20) -> 71 | F21: 100
A23: 硬性否决(任一触发则不得买入) | B23: 状态 | C23: 触发(1) | D23: 说明
A24: 周趋势闸门 | B24: =IF(C24=1,"✗ 否决","✓ 通过") -> ✓ 通过 | C24: =INDEX(日线!$CE$5:$CE$310,$B$5) -> 0 | D24: 形态A要求周EMA慢向上;背离/极端形态B、C不受此限(第39节)
A25: 周线动力系统红色 | B25: =IF(C25=1,"✗ 否决","✓ 通过") -> ✓ 通过 | C25: =INDEX(日线!$CF$5:$CF$310,$B$5) -> 0 | D25: 红色禁止买入(第40节)
A26: 日线动力系统红色 | B26: =IF(C26=1,"✗ 否决","✓ 通过") -> ✓ 通过 | C26: =INDEX(日线!$CG$5:$CG$310,$B$5) -> 0 | D26: 红色禁止买入(第40节)
A27: 无有效买入形态 | B27: =IF(C27=1,"✗ 否决","✓ 通过") -> ✓ 通过 | C27: =INDEX(日线!$CH$5:$CH$310,$B$5) -> 0 | D27: A/B/C 都不满足 = 不是"A级交易"(第55节)
A28: 盈亏比不足 | B28: =IF(C28=1,"✗ 否决","✓ 通过") -> ✓ 通过 | C28: =INDEX(日线!$CI$5:$CI$310,$B$5) -> 0 | D28: 盈亏比必须≥参数(默认2:1)(第38/53节)
A30: 评级(A/B/C) | B30: =INDEX(日线!$CJ$5:$CJ$310,$B$5) -> A | D30: =IF(B30="A","A级交易:按计划挂单",IF(B30="B","B级:仅在额度充足时以1/3风险试探","C级:放弃,翻到下一只(第55节)")) -> A级交易:按计划挂单
A32: 次日挂单计划 | B32: 数值 | D32: 算法
A33: 买入限价 | B33: =INDEX(日线!$AY$5:$AY$310,$B$5) -> 29.39 | D33: 明日EMA估计 − 平均下跌穿透(第39节,以折价回调买入,不追高)
A34: 止损价 | B34: =INDEX(日线!$BA$5:$BA$310,$B$5) -> 28.78 | D34: min(近期次低点−0.01, 买入价−N×ATR),避开整数位(第54节尼克止损)
A35: 目标价 | B35: =INDEX(日线!$BB$5:$BB$310,$B$5) -> 31.38 | D35: 上通道线(第53节:在价值区间下方买、通道上轨获利)
A36: 每股风险 | B36: =B33-B34 -> 0.61 | D36: 买入价−止损价
A37: 盈亏比 | B37: =INDEX(日线!$BC$5:$BC$310,$B$5) -> 3.2622951 | D37: (目标−买入)/(买入−止损)
A38: 大盘风险系数 | B38: =m_Mult -> 1 | D38: 来自"市场温度"
A39: 风险额度(元) | B39: =MIN(p_Equity*MIN(p_RiskTrade,p_RiskCap)*B38,pos_AvailRisk) -> 10000 | D39: 资金×单笔风险%×大盘系数,且不超过6%法则剩余额度
A40: 建议股数 | B40: =IF(AND(B30<>"C",B36>0),FLOOR(MIN(B39/B36,p_Equity*p_PosCap/B33),p_Lot),0) -> 6800 | D40: 铁三角:风险额度÷每股风险,并受单只仓位上限约束,按手取整
A41: 占用资金(元) | B41: =B40*B33 -> 199852
A42: 占账户比例 | B42: =B41/p_Equity -> 0.199852
A44: 提示:分数阈值、权重与市场温度系数是本方案的设计假设(非书中原文),将在第三步用 2026 年 1 月起的历史数据回测校准。

Sheet 日线
A1: 日线数据与指标(A:F 粘贴自己的 OHLCV;其余列全部为公式。向下追加数据时,把最后一行公式整行下拉复制)
A2: ※ 当前为合成示例数据(DEMO),仅用于演示公式,不是真实行情。
A3: 行情(粘贴区) | G3: 趋势 | J3: MACD | O3: 动力系统 | U3: 强力指数 | X3: 波动率/ADX | AI3: 通道 | AQ3: 随机指标 | AV3: 挂单/止损 | BD3: 背离 | BO3: 信号 | BS3: 周线状态(上一完整周) | BV3: 评分
A4: 日期 | B4: 开盘 | C4: 最高 | D4: 最低 | E4: 收盘 | F4: 成交量 | G4: 周键(周一) | H4: EMA快 | I4: EMA慢 | J4: EMA12 | K4: EMA26 | L4: MACD线 | M4: 信号线 | N4: MACD柱 | O4: EMA快↑ | P4: EMA快↓ | Q4: 柱↑ | R4: 柱↓ | S4: 动力系统(1绿/-1红/0蓝) | T4: 颜色 | U4: 强力指数 | V4: FI-2日EMA | W4: FI-13日EMA | X4: 真实波幅TR | Y4: ATR | Z4: +DM | AA4: -DM | AB4: 平滑TR | AC4: 平滑+DM | AD4: 平滑-DM | AE4: +DI | AF4: -DI | AG4: DX | AH4: ADX | AI4: 通道上轨 | AJ4: 通道下轨 | AK4: ATR+1 | AL4: ATR+2 | AM4: ATR+3 | AN4: ATR-1 | AO4: ATR-2 | AP4: ATR-3 | AQ4: N日最高 | AR4: N日最低 | AS4: 原始%K | AT4: 慢%K | AU4: 慢%D | AV4: 下穿EMA快深度 | AW4: 平均下跌穿透 | AX4: 明日EMA估计 | AY4: 买入挂单价 | AZ4: 近期次低点 | BA4: 止损价 | BB4: 目标价(上轨) | BC4: 盈亏比 | BD4: 柱<0 | BE4: 当前区段柱谷 | BF4: 当前区段价低 | BG4: 谷位置 | BH4: 前一谷柱值 | BI4: 前一谷价低 | BJ4: 前谷位置 | BK4: 两谷间隔 | BL4: 牛市背离 | BM4: 向下假突破 | BN4: 强背离 | BO4: FI2非新低 | BP4: FI2负值均值 | BQ4: 极端超卖反弹 | BR4: 5日均量 | BS4: 上周EMA慢↑ | BT4: 上周柱↑ | BU4: 上周动力 | BV4: 形态A回调到价值区 | BW4: 形态B背离 | BX4: 形态C极端 | BY4: 趋势25 | BZ4: 回调25 | CA4: 形态25 | CB4: 量能10 | CC4: 盈亏15 | CD4: 总分 | CE4: 否决:周趋势 | CF4: 否决:周红 | CG4: 否决:日红 | CH4: 否决:无形态 | CI4: 否决:RR<2 | CJ4: 评级
A5: 45659 | B5: 19.79 | C5: 19.94 | D5: 19.66 | E5: 19.82 | F5: 4231300 | G5: =A5-WEEKDAY(A5,3) -> 45656 | H5: =E5 -> 19.82 | I5: =E5 -> 19.82 | J5: =E5 -> 19.82 | K5: =E5 -> 19.82 | L5: =J5-K5 -> 0 | M5: =L5 -> 0 | N5: =L5-M5 -> 0 | O5: =0 -> 0 | P5: =0 -> 0 | Q5: =0 -> 0 | R5: =0 -> 0 | S5: =0 -> 0 | T5: =IF(S5=1,"绿",IF(S5=-1,"红","蓝")) -> 蓝 | U5: =0 -> 0 | V5: =U5 -> 0 | W5: =U5 -> 0 | X5: =C5-D5 -> 0.28 | Y5: =AVERAGE(OFFSET(X5,1-MIN(p_AtrN,ROW()-4),0,MIN(p_AtrN,ROW()-4),1)) -> 0.28 | Z5: =0 -> 0 | AA5: =0 -> 0 | AB5: =X5 -> 0.28 | AC5: =Z5 -> 0 | AD5: =AA5 -> 0 | AE5: =100*AC5/AB5 -> 0 | AF5: =100*AD5/AB5 -> 0 | AG5: =IFERROR(100*ABS(AE5-AF5)/(AE5+AF5),0) -> 0 | AH5: =AG5 -> 0 | AI5: =I5*(1+p_ChPct) -> 21.0092 | AJ5: =I5*(1-p_ChPct) -> 18.6308 | AK5: =I5+1*Y5 -> 20.1 | AL5: =I5+2*Y5 -> 20.38 | AM5: =I5+3*Y5 -> 20.66 | AN5: =I5-1*Y5 -> 19.54 | AO5: =I5-2*Y5 -> 19.26 | AP5: =I5-3*Y5 -> 18.98 | AQ5: =MAX(OFFSET(C5,1-MIN(p_StochN,ROW()-4),0,MIN(p_StochN,ROW()-4),1)) -> 19.94 | AR5: =MIN(OFFSET(D5,1-MIN(p_StochN,ROW()-4),0,MIN(p_StochN,ROW()-4),1)) -> 19.66 | AS5: =IF(AQ5=AR5,50,100*(E5-AR5)/(AQ5-AR5)) -> 57.142857 | AT5: =AVERAGE(OFFSET(AS5,1-MIN(p_StochSm,ROW()-4),0,MIN(p_StochSm,ROW()-4),1)) -> 57.142857 | AU5: =AVERAGE(OFFSET(AT5,1-MIN(p_StochSm,ROW()-4),0,MIN(p_StochSm,ROW()-4),1)) -> 57.142857 | AV5: =MAX(0,H5-D5) -> 0.16 | AW5: =IF(COUNTIF(OFFSET(AV5,1-MIN(p_PenLb,ROW()-4),0,MIN(p_PenLb,ROW()-4),1),">0")>0,SUM(OFFSET(AV5,1-MIN(p_PenLb,ROW()-4),0,MIN(p_PenLb,ROW()-4),1))/COUNTIF(OFFSET(AV5,1-MIN(p_PenLb,ROW()-4),0,MIN(p_PenLb,ROW()-4),1),">0"),0.5*Y5) -> 0.16 | AX5: =H5 -> 19.82 | AY5: =ROUND(MAX(AX5-AW5,0.01),2) -> 19.66 | AZ5: =IF(MIN(p_StopLb,ROW()-4)<2,D5,SMALL(OFFSET(D5,1-MIN(p_StopLb,ROW()-4),0,MIN(p_StopLb,ROW()-4),1),2)) -> 19.66 | BA5: =IF(MOD(ROUND(ROUNDDOWN(MIN(AZ5-0.01,AY5-p_StopAtr*Y5),2)*100,0),50)=0,ROUNDDOWN(MIN(AZ5-0.01,AY5-p_StopAtr*Y5),2)-0.01,ROUNDDOWN(MIN(AZ5-0.01,AY5-p_StopAtr*Y5),2)) -> 19.38 | BB5: =ROUND(AI5,2) -> 21.01 | BC5: =IF(AY5-BA5>0,(BB5-AY5)/(AY5-BA5),0) -> 4.8214286 | BD5: =IF(N5<0,1,0) -> 0 | BE5: =IF(BD5=1,N5,"") | BF5: =IF(BD5=1,D5,"") | BG5: =IF(BD5=1,ROW(),"") | BH5: ="" | BI5: ="" | BJ5: ="" | BK5: =IF(AND(ISNUMBER(BG5),ISNUMBER(BJ5)),BG5-BJ5,"") | BL5: =0 -> 0 | BM5: =0 -> 0 | BN5: =0 -> 0 | BO5: =0 -> 0 | BP5: =IF(COUNTIF(OFFSET(V5,1-MIN(100,ROW()-4),0,MIN(100,ROW()-4),1),"<0")>=5,AVERAGEIF(OFFSET(V5,1-MIN(100,ROW()-4),0,MIN(100,ROW()-4),1),"<0"),"") | BQ5: =0 -> 0 | BR5: =AVERAGE(OFFSET(F5,1-MIN(5,ROW()-4),0,MIN(5,ROW()-4),1)) -> 4231300 | BS5: =IFERROR(IF(MATCH(G5,周线!$A$5:$A$84,0)<=1,"",INDEX(周线!$R$5:$R$84,MATCH(G5,周线!$A$5:$A$84,0)-1)),"") | BT5: =IFERROR(IF(MATCH(G5,周线!$A$5:$A$84,0)<=1,"",INDEX(周线!$S$5:$S$84,MATCH(G5,周线!$A$5:$A$84,0)-1)),"") | BU5: =IFERROR(IF(MATCH(G5,周线!$A$5:$A$84,0)<=1,"",INDEX(周线!$U$5:$U$84,MATCH(G5,周线!$A$5:$A$84,0)-1)),"") | BV5: =IF(AND(BS5=1,S5<>-1,V5<0,BO5=1,E5<=H5,E5>=AJ5),1,0) -> 0 | BW5: =BL5 -> 0 | BX5: =BQ5 -> 0 | BY5: =IF(BS5=1,10,0)+IF(BU5=1,5,IF(BU5=-1,0,3))+IF(BT5=1,5,0)+IF(AND(AE5>AF5,AH5>0),5,0) -> 3 | BZ5: =IF(AND(E5<=H5,E5>=I5),10,IF(AND(E5>=AJ5,E5<I5),6,0))+IF(AND(V5<0,BO5=1),8,0)+IF(AT5<30,7,IF(AT5<50,3,0)) -> 10 | CA5: =IF(AND(BV5=1,BW5=1),25,IF(BW5=1,22,IF(BV5=1,15,IF(BX5=1,12,0)))) -> 0 | CB5: =IF(W5>0,6,0)+IF(F5<BR5,4,0) -> 0 | CC5: =IF(BC5>=3,15,IF(BC5>=p_RRmin,10,IF(BC5>=1.5,4,0))) -> 15 | CD5: =BY5+BZ5+CA5+CB5+CC5 -> 28 | CE5: =IF(AND(BS5<>1,BW5+BX5=0),1,0) -> 1 | CF5: =IF(BU5=-1,1,0) -> 0 | CG5: =IF(S5=-1,1,0) -> 0 | CH5: =IF(BV5+BW5+BX5=0,1,0) -> 1 | CI5: =IF(BC5<p_RRmin,1,0) -> 0 | CJ5: =IF(SUM(CE5:CI5)=0,IF(CD5>=p_GradeA,"A",IF(CD5>=p_GradeB,"B","C")),IF(AND(CI5=1,SUM(CE5:CH5)=0,CD5>=p_GradeB),"B","C")) -> C
A6: 45660 | B6: 19.86 | C6: 20.15 | D6: 19.8 | E6: 20.09 | F6: 2822100 | G6: =A6-WEEKDAY(A6,3) -> 45656 | H6: =2/(p_EmaF+1)*E6+(1-2/(p_EmaF+1))*H5 -> 19.858571 | I6: =2/(p_EmaS+1)*E6+(1-2/(p_EmaS+1))*I5 -> 19.84 | J6: =2/(p_MacdF+1)*E6+(1-2/(p_MacdF+1))*J5 -> 19.861538 | K6: =2/(p_MacdS+1)*E6+(1-2/(p_MacdS+1))*K5 -> 19.84 | L6: =J6-K6 -> 0.021538462 | M6: =2/(p_MacdSig+1)*L6+(1-2/(p_MacdSig+1))*M5 -> 0.0043076923 | N6: =L6-M6 -> 0.017230769 | O6: =IF(H6>H5,1,0) -> 1 | P6: =IF(H6<H5,1,0) -> 0 | Q6: =IF(N6>N5,1,0) -> 1 | R6: =IF(N6<N5,1,0) -> 0 | S6: =IF(AND(O6=1,Q6=1),1,IF(AND(P6=1,R6=1),-1,0)) -> 1 | T6: =IF(S6=1,"绿",IF(S6=-1,"红","蓝")) -> 绿 | U6: =F6*(E6-E5) -> 761967 | V6: =2/(p_FiS+1)*U6+(1-2/(p_FiS+1))*V5 -> 507978 | W6: =2/(p_FiL+1)*U6+(1-2/(p_FiL+1))*W5 -> 108852.43 | X6: =MAX(C6-D6,ABS(C6-E5),ABS(D6-E5)) -> 0.35 | Y6: =AVERAGE(OFFSET(X6,1-MIN(p_AtrN,ROW()-4),0,MIN(p_AtrN,ROW()-4),1)) -> 0.315 | Z6: =IF(AND(C6-C5>D5-D6,C6-C5>0),C6-C5,0) -> 0.21 | AA6: =IF(AND(D5-D6>C6-C5,D5-D6>0),D5-D6,0) -> 0 | AB6: =2/(p_AdxN+1)*X6+(1-2/(p_AdxN+1))*AB5 -> 0.29 | AC6: =2/(p_AdxN+1)*Z6+(1-2/(p_AdxN+1))*AC5 -> 0.03 | AD6: =2/(p_AdxN+1)*AA6+(1-2/(p_AdxN+1))*AD5 -> 0 | AE6: =100*AC6/AB6 -> 10.344828 | AF6: =100*AD6/AB6 -> 0 | AG6: =IFERROR(100*ABS(AE6-AF6)/(AE6+AF6),0) -> 100 | AH6: =2/(p_AdxN+1)*AG6+(1-2/(p_AdxN+1))*AH5 -> 14.285714 | AI6: =I6*(1+p_ChPct) -> 21.0304 | AJ6: =I6*(1-p_ChPct) -> 18.6496 | AK6: =I6+1*Y6 -> 20.155 | AL6: =I6+2*Y6 -> 20.47 | AM6: =I6+3*Y6 -> 20.785 | AN6: =I6-1*Y6 -> 19.525 | AO6: =I6-2*Y6 -> 19.21 | AP6: =I6-3*Y6 -> 18.895 | AQ6: =MAX(OFFSET(C6,1-MIN(p_StochN,ROW()-4),0,MIN(p_StochN,ROW()-4),1)) -> 20.15 | AR6: =MIN(OFFSET(D6,1-MIN(p_StochN,ROW()-4),0,MIN(p_StochN,ROW()-4),1)) -> 19.66 | AS6: =IF(AQ6=AR6,50,100*(E6-AR6)/(AQ6-AR6)) -> 87.755102 | AT6: =AVERAGE(OFFSET(AS6,1-MIN(p_StochSm,ROW()-4),0,MIN(p_StochSm,ROW()-4),1)) -> 72.44898 | AU6: =AVERAGE(OFFSET(AT6,1-MIN(p_StochSm,ROW()-4),0,MIN(p_StochSm,ROW()-4),1)) -> 64.795918 | AV6: =MAX(0,H6-D6) -> 0.058571429 | AW6: =IF(COUNTIF(OFFSET(AV6,1-MIN(p_PenLb,ROW()-4),0,MIN(p_PenLb,ROW()-4),1),">0")>0,SUM(OFFSET(AV6,1-MIN(p_PenLb,ROW()-4),0,MIN(p_PenLb,ROW()-4),1))/COUNTIF(OFFSET(AV6,1-MIN(p_PenLb,ROW()-4),0,MIN(p_PenLb,ROW()-4),1),">0"),0.5*Y6) -> 0.10928571 | AX6: =2*H6-H5 -> 19.897143 | AY6: =ROUND(MAX(AX6-AW6,0.01),2) -> 19.79 | AZ6: =IF(MIN(p_StopLb,ROW()-4)<2,D6,SMALL(OFFSET(D6,1-MIN(p_StopLb,ROW()-4),0,MIN(p_StopLb,ROW()-4),1),2)) -> 19.8 | BA6: =IF(MOD(ROUND(ROUNDDOWN(MIN(AZ6-0.01,AY6-p_StopAtr*Y6),2)*100,0),50)=0,ROUNDDOWN(MIN(AZ6-0.01,AY6-p_StopAtr*Y6),2)-0.01,ROUNDDOWN(MIN(AZ6-0.01,AY6-p_StopAtr*Y6),2)) -> 19.47 | BB6: =ROUND(AI6,2) -> 21.03 | BC6: =IF(AY6-BA6>0,(BB6-AY6)/(AY6-BA6),0) -> 3.875 | BD6: =IF(N6<0,1,0) -> 0 | BE6: =IF(AND(BD6=1,BD5=0),N6,IF(BD6=1,MIN(BE5,N6),BE5)) | BF6: =IF(AND(BD6=1,BD5=0),D6,IF(BD6=1,MIN(BF5,D6),BF5)) | BG6: =IF(AND(BD6=1,BD5=0),ROW(),IF(BD6=1,IF(N6<BE5,ROW(),BG5),BG5)) | BH6: =IF(AND(BD6=1,BD5=0),BE5,BH5) | BI6: =IF(AND(BD6=1,BD5=0),BF5,BI5) | BJ6: =IF(AND(BD6=1,BD5=0),BG5,BJ5) | BK6: =IF(AND(ISNUMBER(BG6),ISNUMBER(BJ6)),BG6-BJ6,"") | BL6: =IF(AND(BD6=1,N6>N5,ISNUMBER(BH6),ISNUMBER(BK6)),IF(AND(BE6>BH6,BF6<BI6,BK6>=p_GapMin,BK6<=p_GapMax),1,0),0) -> 0 | BM6: =IF(AND(BL6=1,E6>BI6),1,0) -> 0 | BN6: =IF(BL6=1,IF(BE6>=BH6*0.5,1,0),0) -> 0 | BO6: =IF(V6>MIN(OFFSET(V6,-MIN(p_FiLb-1,ROW()-5),0,MIN(p_FiLb-1,ROW()-5),1)),1,0) -> 1 | BP6: =IF(COUNTIF(OFFSET(V6,1-MIN(100,ROW()-4),0,MIN(100,ROW()-4),1),"<0")>=5,AVERAGEIF(OFFSET(V6,1-MIN(100,ROW()-4),0,MIN(100,ROW()-4),1),"<0"),"") | BQ6: =IF(ISNUMBER(BP6),IF(AND(V6<5*BP6,V6>V5,E6<AJ6),1,0),0) -> 0 | BR6: =AVERAGE(OFFSET(F6,1-MIN(5,ROW()-4),0,MIN(5,ROW()-4),1)) -> 3526700 | BS6: =IFERROR(IF(MATCH(G6,周线!$A$5:$A$84,0)<=1,"",INDEX(周线!$R$5:$R$84,MATCH(G6,周线!$A$5:$A$84,0)-1)),"") | BT6: =IFERROR(IF(MATCH(G6,周线!$A$5:$A$84,0)<=1,"",INDEX(周线!$S$5:$S$84,MATCH(G6,周线!$A$5:$A$84,0)-1)),"") | BU6: =IFERROR(IF(MATCH(G6,周线!$A$5:$A$84,0)<=1,"",INDEX(周线!$U$5:$U$84,MATCH(G6,周线!$A$5:$A$84,0)-1)),"") | BV6: =IF(AND(BS6=1,S6<>-1,V6<0,BO6=1,E6<=H6,E6>=AJ6),1,0) -> 0 | BW6: =BL6 -> 0 | BX6: =BQ6 -> 0 | BY6: =IF(BS6=1,10,0)+IF(BU6=1,5,IF(BU6=-1,0,3))+IF(BT6=1,5,0)+IF(AND(AE6>AF6,AH6>AH5),5,0) -> 8 | BZ6: =IF(AND(E6<=H6,E6>=I6),10,IF(AND(E6>=AJ6,E6<I6),6,0))+IF(AND(V6<0,BO6=1),8,0)+IF(AT6<30,7,IF(AT6<50,3,0)) -> 0 | CA6: =IF(AND(BV6=1,BW6=1),25,IF(BW6=1,22,IF(BV6=1,15,IF(BX6=1,12,0)))) -> 0 | CB6: =IF(W6>0,6,0)+IF(F6<BR6,4,0) -> 10 | CC6: =IF(BC6>=3,15,IF(BC6>=p_RRmin,10,IF(BC6>=1.5,4,0))) -> 15 | CD6: =BY6+BZ6+CA6+CB6+CC6 -> 33 | CE6: =IF(AND(BS6<>1,BW6+BX6=0),1,0) -> 1 | CF6: =IF(BU6=-1,1,0) -> 0 | CG6: =IF(S6=-1,1,0) -> 0 | CH6: =IF(BV6+BW6+BX6=0,1,0) -> 1 | CI6: =IF(BC6<p_RRmin,1,0) -> 0 | CJ6: =IF(SUM(CE6:CI6)=0,IF(CD6>=p_GradeA,"A",IF(CD6>=p_GradeB,"B","C")),IF(AND(CI6=1,SUM(CE6:CH6)=0,CD6>=p_GradeB),"B","C")) -> C
A7: 45663 | B7: 20.05 | C7: 20.26 | D7: 19.75 | E7: 19.86 | F7: 3844400 | G7: =A7-WEEKDAY(A7,3) -> 45663 | H7: =2/(p_EmaF+1)*E7+(1-2/(p_EmaF+1))*H6 -> 19.858776 | I7: =2/(p_EmaS+1)*E7+(1-2/(p_EmaS+1))*I6 -> 19.841481 | J7: =2/(p_MacdF+1)*E7+(1-2/(p_MacdF+1))*J6 -> 19.861302 | K7: =2/(p_MacdS+1)*E7+(1-2/(p_MacdS+1))*K6 -> 19.841481 | L7: =J7-K7 -> 0.019820294 | M7: =2/(p_MacdSig+1)*L7+(1-2/(p_MacdSig+1))*M6 -> 0.0074102126 | N7: =L7-M7 -> 0.012410081 | O7: =IF(H7>H6,1,0) -> 1 | P7: =IF(H7<H6,1,0) -> 0 | Q7: =IF(N7>N6,1,0) -> 0 | R7: =IF(N7<N6,1,0) -> 1 | S7: =IF(AND(O7=1,Q7=1),1,IF(AND(P7=1,R7=1),-1,0)) -> 0 | T7: =IF(S7=1,"绿",IF(S7=-1,"红","蓝")) -> 蓝 | U7: =F7*(E7-E6) -> -884212 | V7: =2/(p_FiS+1)*U7+(1-2/(p_FiS+1))*V6 -> -420148.67 | W7: =2/(p_FiL+1)*U7+(1-2/(p_FiL+1))*W6 -> -33013.918 | X7: =MAX(C7-D7,ABS(C7-E6),ABS(D7-E6)) -> 0.51 | Y7: =AVERAGE(OFFSET(X7,1-MIN(p_AtrN,ROW()-4),0,MIN(p_AtrN,ROW()-4),1)) -> 0.38 | Z7: =IF(AND(C7-C6>D6-D7,C7-C6>0),C7-C6,0) -> 0.11 | AA7: =IF(AND(D6-D7>C7-C6,D6-D7>0),D6-D7,0) -> 0 | AB7: =2/(p_AdxN+1)*X7+(1-2/(p_AdxN+1))*AB6 -> 0.32142857 | AC7: =2/(p_AdxN+1)*Z7+(1-2/(p_AdxN+1))*AC6 -> 0.041428571 | AD7: =2/(p_AdxN+1)*AA7+(1-2/(p_AdxN+1))*AD6 -> 0 | AE7: =100*AC7/AB7 -> 12.888889 | AF7: =100*AD7/AB7 -> 0 | AG7: =IFERROR(100*ABS(AE7-AF7)/(AE7+AF7),0) -> 100 | AH7: =2/(p_AdxN+1)*AG7+(1-2/(p_AdxN+1))*AH6 -> 26.530612 | AI7: =I7*(1+p_ChPct) -> 21.03197 | AJ7: =I7*(1-p_ChPct) -> 18.650993 | AK7: =I7+1*Y7 -> 20.221481 | AL7: =I7+2*Y7 -> 20.601481 | AM7: =I7+3*Y7 -> 20.981481 | AN7: =I7-1*Y7 -> 19.461481 | AO7: =I7-2*Y7 -> 19.081481 | AP7: =I7-3*Y7 -> 18.701481 | AQ7: =MAX(OFFSET(C7,1-MIN(p_StochN,ROW()-4),0,MIN(p_StochN,ROW()-4),1)) -> 20.26 | AR7: =MIN(OFFSET(D7,1-MIN(p_StochN,ROW()-4),0,MIN(p_StochN,ROW()-4),1)) -> 19.66 | AS7: =IF(AQ7=AR7,50,100*(E7-AR7)/(AQ7-AR7)) -> 33.333333 | AT7: =AVERAGE(OFFSET(AS7,1-MIN(p_StochSm,ROW()-4),0,MIN(p_StochSm,ROW()-4),1)) -> 59.410431 | AU7: =AVERAGE(OFFSET(AT7,1-MIN(p_StochSm,ROW()-4),0,MIN(p_StochSm,ROW()-4),1)) -> 63.000756 | AV7: =MAX(0,H7-D7) -> 0.10877551 | AW7: =IF(COUNTIF(OFFSET(AV7,1-MIN(p_PenLb,ROW()-4),0,MIN(p_PenLb,ROW()-4),1),">0")>0,SUM(OFFSET(AV7,1-MIN(p_PenLb,ROW()-4),0,MIN(p_PenLb,ROW()-4),1))/COUNTIF(OFFSET(AV7,1-MIN(p_PenLb,ROW()-4),0,MIN(p_PenLb,ROW()-4),1),">0"),0.5*Y7) -> 0.10911565 | AX7: =2*H7-H6 -> 19.85898 | AY7: =ROUND(MAX(AX7-AW7,0.01),2) -> 19.75 | AZ7: =IF(MIN(p_StopLb,ROW()-4)<2,D7,SMALL(OFFSET(D7,1-MIN(p_StopLb,ROW()-4),0,MIN(p_StopLb,ROW()-4),1),2)) -> 19.75 | BA7: =IF(MOD(ROUND(ROUNDDOWN(MIN(AZ7-0.01,AY7-p_StopAtr*Y7),2)*100,0),50)=0,ROUNDDOWN(MIN(AZ7-0.01,AY7-p_StopAtr*Y7),2)-0.01,ROUNDDOWN(MIN(AZ7-0.01,AY7-p_StopAtr*Y7),2)) -> 19.37 | BB7: =ROUND(AI7,2) -> 21.03 | BC7: =IF(AY7-BA7>0,(BB7-AY7)/(AY7-BA7),0) -> 3.3684211 | BD7: =IF(N7<0,1,0) -> 0 | BE7: =IF(AND(BD7=1,BD6=0),N7,IF(BD7=1,MIN(BE6,N7),BE6)) | BF7: =IF(AND(BD7=1,BD6=0),D7,IF(BD7=1,MIN(BF6,D7),BF6)) | BG7: =IF(AND(BD7=1,BD6=0),ROW(),IF(BD7=1,IF(N7<BE6,ROW(),BG6),BG6)) | BH7: =IF(AND(BD7=1,BD6=0),BE6,BH6) | BI7: =IF(AND(BD7=1,BD6=0),BF6,BI6) | BJ7: =IF(AND(BD7=1,BD6=0),BG6,BJ6) | BK7: =IF(AND(ISNUMBER(BG7),ISNUMBER(BJ7)),BG7-BJ7,"") | BL7: =IF(AND(BD7=1,N7>N6,ISNUMBER(BH7),ISNUMBER(BK7)),IF(AND(BE7>BH7,BF7<BI7,BK7>=p_GapMin,BK7<=p_GapMax),1,0),0) -> 0 | BM7: =IF(AND(BL7=1,E7>BI7),1,0) -> 0 | BN7: =IF(BL7=1,IF(BE7>=BH7*0.5,1,0),0) -> 0 | BO7: =IF(V7>MIN(OFFSET(V7,-MIN(p_FiLb-1,ROW()-5),0,MIN(p_FiLb-1,ROW()-5),1)),1,0) -> 0 | BP7: =IF(COUNTIF(OFFSET(V7,1-MIN(100,ROW()-4),0,MIN(100,ROW()-4),1),"<0")>=5,AVERAGEIF(OFFSET(V7,1-MIN(100,ROW()-4),0,MIN(100,ROW()-4),1),"<0"),"") | BQ7: =IF(ISNUMBER(BP7),IF(AND(V7<5*BP7,V7>V6,E7<AJ7),1,0),0) -> 0 | BR7: =AVERAGE(OFFSET(F7,1-MIN(5,ROW()-4),0,MIN(5,ROW()-4),1)) -> 3632600 | BS7: =IFERROR(IF(MATCH(G7,周线!$A$5:$A$84,0)<=1,"",INDEX(周线!$R$5:$R$84,MATCH(G7,周线!$A$5:$A$84,0)-1)),"") -> 0 | BT7: =IFERROR(IF(MATCH(G7,周线!$A$5:$A$84,0)<=1,"",INDEX(周线!$S$5:$S$84,MATCH(G7,周线!$A$5:$A$84,0)-1)),"") -> 0 | BU7: =IFERROR(IF(MATCH(G7,周线!$A$5:$A$84,0)<=1,"",INDEX(周线!$U$5:$U$84,MATCH(G7,周线!$A$5:$A$84,0)-1)),"") -> 0 | BV7: =IF(AND(BS7=1,S7<>-1,V7<0,BO7=1,E7<=H7,E7>=AJ7),1,0) -> 0 | BW7: =BL7 -> 0 | BX7: =BQ7 -> 0 | BY7: =IF(BS7=1,10,0)+IF(BU7=1,5,IF(BU7=-1,0,3))+IF(BT7=1,5,0)+IF(AND(AE7>AF7,AH7>AH6),5,0) -> 8 | BZ7: =IF(AND(E7<=H7,E7>=I7),10,IF(AND(E7>=AJ7,E7<I7),6,0))+IF(AND(V7<0,BO7=1),8,0)+IF(AT7<30,7,IF(AT7<50,3,0)) -> 0 | CA7: =IF(AND(BV7=1,BW7=1),25,IF(BW7=1,22,IF(BV7=1,15,IF(BX7=1,12,0)))) -> 0 | CB7: =IF(W7>0,6,0)+IF(F7<BR7,4,0) -> 0 | CC7: =IF(BC7>=3,15,IF(BC7>=p_RRmin,10,IF(BC7>=1.5,4,0))) -> 15 | CD7: =BY7+BZ7+CA7+CB7+CC7 -> 23 | CE7: =IF(AND(BS7<>1,BW7+BX7=0),1,0) -> 1 | CF7: =IF(BU7=-1,1,0) -> 0 | CG7: =IF(S7=-1,1,0) -> 0 | CH7: =IF(BV7+BW7+BX7=0,1,0) -> 1 | CI7: =IF(BC7<p_RRmin,1,0) -> 0 | CJ7: =IF(SUM(CE7:CI7)=0,IF(CD7>=p_GradeA,"A",IF(CD7>=p_GradeB,"B","C")),IF(AND(CI7=1,SUM(CE7:CH7)=0,CD7>=p_GradeB),"B","C")) -> C
A8: 45664 | B8: 19.91 | C8: 19.99 | D8: 19.48 | E8: 19.66 | F8: 3603000 | G8: =A8-WEEKDAY(A8,3) -> 45663 | H8: =2/(p_EmaF+1)*E8+(1-2/(p_EmaF+1))*H7 -> 19.830379 | I8: =2/(p_EmaS+1)*E8+(1-2/(p_EmaS+1))*I7 -> 19.828038 | J8: =2/(p_MacdF+1)*E8+(1-2/(p_MacdF+1))*J7 -> 19.830332 | K8: =2/(p_MacdS+1)*E8+(1-2/(p_MacdS+1))*K7 -> 19.828038 | L8: =J8-K8 -> 0.0022938625 | M8: =2/(p_MacdSig+1)*L8+(1-2/(p_MacdSig+1))*M7 -> 0.0063869426 | N8: =L8-M8 -> -0.0040930801 | O8: =IF(H8>H7,1,0) -> 0 | P8: =IF(H8<H7,1,0) -> 1 | Q8: =IF(N8>N7,1,0) -> 0 | R8: =IF(N8<N7,1,0) -> 1 | S8: =IF(AND(O8=1,Q8=1),1,IF(AND(P8=1,R8=1),-1,0)) -> -1 | T8: =IF(S8=1,"绿",IF(S8=-1,"红","蓝")) -> 红 | U8: =F8*(E8-E7) -> -720600 | V8: =2/(p_FiS+1)*U8+(1-2/(p_FiS+1))*V7 -> -620449.56 | W8: =2/(p_FiL+1)*U8+(1-2/(p_FiL+1))*W7 -> -131240.5 | X8: =MAX(C8-D8,ABS(C8-E7),ABS(D8-E7)) -> 0.51 | Y8: =AVERAGE(OFFSET(X8,1-MIN(p_AtrN,ROW()-4),0,MIN(p_AtrN,ROW()-4),1)) -> 0.4125 | Z8: =IF(AND(C8-C7>D7-D8,C8-C7>0),C8-C7,0) -> 0 | AA8: =IF(AND(D7-D8>C8-C7,D7-D8>0),D7-D8,0) -> 0.27 | AB8: =2/(p_AdxN+1)*X8+(1-2/(p_AdxN+1))*AB7 -> 0.34836735 | AC8: =2/(p_AdxN+1)*Z8+(1-2/(p_AdxN+1))*AC7 -> 0.035510204 | AD8: =2/(p_AdxN+1)*AA8+(1-2/(p_AdxN+1))*AD7 -> 0.038571429 | AE8: =100*AC8/AB8 -> 10.193322 | AF8: =100*AD8/AB8 -> 11.072056 | AG8: =IFERROR(100*ABS(AE8-AF8)/(AE8+AF8),0) -> 4.1322314 | AH8: =2/(p_AdxN+1)*AG8+(1-2/(p_AdxN+1))*AH7 -> 23.330844 | AI8: =I8*(1+p_ChPct) -> 21.017721 | AJ8: =I8*(1-p_ChPct) -> 18.638356 | AK8: =I8+1*Y8 -> 20.240538 | AL8: =I8+2*Y8 -> 20.653038 | AM8: =I8+3*Y8 -> 21.065538 | AN8: =I8-1*Y8 -> 19.415538 | AO8: =I8-2*Y8 -> 19.003038 | AP8: =I8-3*Y8 -> 18.590538 | AQ8: =MAX(OFFSET(C8,1-MIN(p_StochN,ROW()-4),0,MIN(p_StochN,ROW()-4),1)) -> 20.26 | AR8: =MIN(OFFSET(D8,1-MIN(p_StochN,ROW()-4),0,MIN(p_StochN,ROW()-4),1)) -> 19.48 | AS8: =IF(AQ8=AR8,50,100*(E8-AR8)/(AQ8-AR8)) -> 23.076923 | AT8: =AVERAGE(OFFSET(AS8,1-MIN(p_StochSm,ROW()-4),0,MIN(p_StochSm,ROW()-4),1)) -> 48.055119 | AU8: =AVERAGE(OFFSET(AT8,1-MIN(p_StochSm,ROW()-4),0,MIN(p_StochSm,ROW()-4),1)) -> 59.97151 | AV8: =MAX(0,H8-D8) -> 0.35037901 | AW8: =IF(COUNTIF(OFFSET(AV8,1-MIN(p_PenLb,ROW()-4),0,MIN(p_PenLb,ROW()-4),1),">0")>0,SUM(OFFSET(AV8,1-MIN(p_PenLb,ROW()-4),0,MIN(p_PenLb,ROW()-4),1))/COUNTIF(OFFSET(AV8,1-MIN(p_PenLb,ROW()-4),0,MIN(p_PenLb,ROW()-4),1),">0"),0.5*Y8) -> 0.16943149 | AX8: =2*H8-H7 -> 19.801983 | AY8: =ROUND(MAX(AX8-AW8,0.01),2) -> 19.63 | AZ8: =IF(MIN(p_StopLb,ROW()-4)<2,D8,SMALL(OFFSET(D8,1-MIN(p_StopLb,ROW()-4),0,MIN(p_StopLb,ROW()-4),1),2)) -> 19.66 | BA8: =IF(MOD(ROUND(ROUNDDOWN(MIN(AZ8-0.01,AY8-p_StopAtr*Y8),2)*100,0),50)=0,ROUNDDOWN(MIN(AZ8-0.01,AY8-p_StopAtr*Y8),2)-0.01,ROUNDDOWN(MIN(AZ8-0.01,AY8-p_StopAtr*Y8),2)) -> 19.21 | BB8: =ROUND(AI8,2) -> 21.02 | BC8: =IF(AY8-BA8>0,(BB8-AY8)/(AY8-BA8),0) -> 3.3095238 | BD8: =IF(N8<0,1,0) -> 1 | BE8: =IF(AND(BD8=1,BD7=0),N8,IF(BD8=1,MIN(BE7,N8),BE7)) -> -0.0040930801 | BF8: =IF(AND(BD8=1,BD7=0),D8,IF(BD8=1,MIN(BF7,D8),BF7)) -> 19.48 | BG8: =IF(AND(BD8=1,BD7=0),ROW(),IF(BD8=1,IF(N8<BE7,ROW(),BG7),BG7)) -> 8 | BH8: =IF(AND(BD8=1,BD7=0),BE7,BH7) | BI8: =IF(AND(BD8=1,BD7=0),BF7,BI7) | BJ8: =IF(AND(BD8=1,BD7=0),BG7,BJ7) | BK8: =IF(AND(ISNUMBER(BG8),ISNUMBER(BJ8)),BG8-BJ8,"") | BL8: =IF(AND(BD8=1,N8>N7,ISNUMBER(BH8),ISNUMBER(BK8)),IF(AND(BE8>BH8,BF8<BI8,BK8>=p_GapMin,BK8<=p_GapMax),1,0),0) -> 0 | BM8: =IF(AND(BL8=1,E8>BI8),1,0) -> 0 | BN8: =IF(BL8=1,IF(BE8>=BH8*0.5,1,0),0) -> 0 | BO8: =IF(V8>MIN(OFFSET(V8,-MIN(p_FiLb-1,ROW()-5),0,MIN(p_FiLb-1,ROW()-5),1)),1,0) -> 0 | BP8: =IF(COUNTIF(OFFSET(V8,1-MIN(100,ROW()-4),0,MIN(100,ROW()-4),1),"<0")>=5,AVERAGEIF(OFFSET(V8,1-MIN(100,ROW()-4),0,MIN(100,ROW()-4),1),"<0"),"") | BQ8: =IF(ISNUMBER(BP8),IF(AND(V8<5*BP8,V8>V7,E8<AJ8),1,0),0) -> 0 | BR8: =AVERAGE(OFFSET(F8,1-MIN(5,ROW()-4),0,MIN(5,ROW()-4),1)) -> 3625200 | BS8: =IFERROR(IF(MATCH(G8,周线!$A$5:$A$84,0)<=1,"",INDEX(周线!$R$5:$R$84,MATCH(G8,周线!$A$5:$A$84,0)-1)),"") -> 0 | BT8: =IFERROR(IF(MATCH(G8,周线!$A$5:$A$84,0)<=1,"",INDEX(周线!$S$5:$S$84,MATCH(G8,周线!$A$5:$A$84,0)-1)),"") -> 0 | BU8: =IFERROR(IF(MATCH(G8,周线!$A$5:$A$84,0)<=1,"",INDEX(周线!$U$5:$U$84,MATCH(G8,周线!$A$5:$A$84,0)-1)),"") -> 0 | BV8: =IF(AND(BS8=1,S8<>-1,V8<0,BO8=1,E8<=H8,E8>=AJ8),1,0) -> 0 | BW8: =BL8 -> 0 | BX8: =BQ8 -> 0 | BY8: =IF(BS8=1,10,0)+IF(BU8=1,5,IF(BU8=-1,0,3))+IF(BT8=1,5,0)+IF(AND(AE8>AF8,AH8>AH7),5,0) -> 3 | BZ8: =IF(AND(E8<=H8,E8>=I8),10,IF(AND(E8>=AJ8,E8<I8),6,0))+IF(AND(V8<0,BO8=1),8,0)+IF(AT8<30,7,IF(AT8<50,3,0)) -> 9 | CA8: =IF(AND(BV8=1,BW8=1),25,IF(BW8=1,22,IF(BV8=1,15,IF(BX8=1,12,0)))) -> 0 | CB8: =IF(W8>0,6,0)+IF(F8<BR8,4,0) -> 4 | CC8: =IF(BC8>=3,15,IF(BC8>=p_RRmin,10,IF(BC8>=1.5,4,0))) -> 15 | CD8: =BY8+BZ8+CA8+CB8+CC8 -> 31 | CE8: =IF(AND(BS8<>1,BW8+BX8=0),1,0) -> 1 | CF8: =IF(BU8=-1,1,0) -> 0 | CG8: =IF(S8=-1,1,0) -> 1 | CH8: =IF(BV8+BW8+BX8=0,1,0) -> 1 | CI8: =IF(BC8<p_RRmin,1,0) -> 0 | CJ8: =IF(SUM(CE8:CI8)=0,IF(CD8>=p_GradeA,"A",IF(CD8>=p_GradeB,"B","C")),IF(AND(CI8=1,SUM(CE8:CH8)=0,CD8>=p_GradeB),"B","C")) -> C
A9: 45665 | B9: 19.61 | C9: 19.69 | D9: 19.42 | E9: 19.53 | F9: 3016400 | G9: =A9-WEEKDAY(A9,3) -> 45663 | H9: =2/(p_EmaF+1)*E9+(1-2/(p_EmaF+1))*H8 -> 19.787468 | I9: =2/(p_EmaS+1)*E9+(1-2/(p_EmaS+1))*I8 -> 19.805961 | J9: =2/(p_MacdF+1)*E9+(1-2/(p_MacdF+1))*J8 -> 19.784127 | K9: =2/(p_MacdS+1)*E9+(1-2/(p_MacdS+1))*K8 -> 19.805961 | L9: =J9-K9 -> -0.021834183 | M9: =2/(p_MacdSig+1)*L9+(1-2/(p_MacdSig+1))*M8 -> 0.00074271742 | N9: =L9-M9 -> -0.022576901 | O9: =IF(H9>H8,1,0) -> 0 | P9: =IF(H9<H8,1,0) -> 1 | Q9: =IF(N9>N8,1,0) -> 0 | R9: =IF(N9<N8,1,0) -> 1 | S9: =IF(AND(O9=1,Q9=1),1,IF(AND(P9=1,R9=1),-1,0)) -> -1 | T9: =IF(S9=1,"绿",IF(S9=-1,"红","蓝")) -> 红 | U9: =F9*(E9-E8) -> -392132 | V9: =2/(p_FiS+1)*U9+(1-2/(p_FiS+1))*V8 -> -468237.85 | W9: =2/(p_FiL+1)*U9+(1-2/(p_FiL+1))*W8 -> -168510.72 | X9: =MAX(C9-D9,ABS(C9-E8),ABS(D9-E8)) -> 0.27 | Y9: =AVERAGE(OFFSET(X9,1-MIN(p_AtrN,ROW()-4),0,MIN(p_AtrN,ROW()-4),1)) -> 0.384 | Z9: =IF(AND(C9-C8>D8-D9,C9-C8>0),C9-C8,0) -> 0 | AA9: =IF(AND(D8-D9>C9-C8,D8-D9>0),D8-D9,0) -> 0.06 | AB9: =2/(p_AdxN+1)*X9+(1-2/(p_AdxN+1))*AB8 -> 0.33717201 | AC9: =2/(p_AdxN+1)*Z9+(1-2/(p_AdxN+1))*AC8 -> 0.030437318 | AD9: =2/(p_AdxN+1)*AA9+(1-2/(p_AdxN+1))*AD8 -> 0.041632653 | AE9: =100*AC9/AB9 -> 9.0272374 | AF9: =100*AD9/AB9 -> 12.347601 | AG9: =IFERROR(100*ABS(AE9-AF9)/(AE9+AF9),0) -> 15.533981 | AH9: =2/(p_AdxN+1)*AG9+(1-2/(p_AdxN+1))*AH8 -> 22.217006 | AI9: =I9*(1+p_ChPct) -> 20.994319 | AJ9: =I9*(1-p_ChPct) -> 18.617604 | AK9: =I9+1*Y9 -> 20.189961 | AL9: =I9+2*Y9 -> 20.573961 | AM9: =I9+3*Y9 -> 20.957961 | AN9: =I9-1*Y9 -> 19.421961 | AO9: =I9-2*Y9 -> 19.037961 | AP9: =I9-3*Y9 -> 18.653961 | AQ9: =MAX(OFFSET(C9,1-MIN(p_StochN,ROW()-4),0,MIN(p_StochN,ROW()-4),1)) -> 20.26 | AR9: =MIN(OFFSET(D9,1-MIN(p_StochN,ROW()-4),0,MIN(p_StochN,ROW()-4),1)) -> 19.42 | AS9: =IF(AQ9=AR9,50,100*(E9-AR9)/(AQ9-AR9)) -> 13.095238 | AT9: =AVERAGE(OFFSET(AS9,1-MIN(p_StochSm,ROW()-4),0,MIN(p_StochSm,ROW()-4),1)) -> 23.168498 | AU9: =AVERAGE(OFFSET(AT9,1-MIN(p_StochSm,ROW()-4),0,MIN(p_StochSm,ROW()-4),1)) -> 43.544683 | AV9: =MAX(0,H9-D9) -> 0.36746772 | AW9: =IF(COUNTIF(OFFSET(AV9,1-MIN(p_PenLb,ROW()-4),0,MIN(p_PenLb,ROW()-4),1),">0")>0,SUM(OFFSET(AV9,1-MIN(p_PenLb,ROW()-4),0,MIN(p_PenLb,ROW()-4),1))/COUNTIF(OFFSET(AV9,1-MIN(p_PenLb,ROW()-4),0,MIN(p_PenLb,ROW()-4),1),">0"),0.5*Y9) -> 0.20903873 | AX9: =2*H9-H8 -> 19.744556 | AY9: =ROUND(MAX(AX9-AW9,0.01),2) -> 19.54 | AZ9: =IF(MIN(p_StopLb,ROW()-4)<2,D9,SMALL(OFFSET(D9,1-MIN(p_StopLb,ROW()-4),0,MIN(p_StopLb,ROW()-4),1),2)) -> 19.48 | BA9: =IF(MOD(ROUND(ROUNDDOWN(MIN(AZ9-0.01,AY9-p_StopAtr*Y9),2)*100,0),50)=0,ROUNDDOWN(MIN(AZ9-0.01,AY9-p_StopAtr*Y9),2)-0.01,ROUNDDOWN(MIN(AZ9-0.01,AY9-p_StopAtr*Y9),2)) -> 19.15 | BB9: =ROUND(AI9,2) -> 20.99 | BC9: =IF(AY9-BA9>0,(BB9-AY9)/(AY9-BA9),0) -> 3.7179487 | BD9: =IF(N9<0,1,0) -> 1 | BE9: =IF(AND(BD9=1,BD8=0),N9,IF(BD9=1,MIN(BE8,N9),BE8)) -> -0.022576901 | BF9: =IF(AND(BD9=1,BD8=0),D9,IF(BD9=1,MIN(BF8,D9),BF8)) -> 19.42 | BG9: =IF(AND(BD9=1,BD8=0),ROW(),IF(BD9=1,IF(N9<BE8,ROW(),BG8),BG8)) -> 9 | BH9: =IF(AND(BD9=1,BD8=0),BE8,BH8) | BI9: =IF(AND(BD9=1,BD8=0),BF8,BI8) | BJ9: =IF(AND(BD9=1,BD8=0),BG8,BJ8) | BK9: =IF(AND(ISNUMBER(BG9),ISNUMBER(BJ9)),BG9-BJ9,"") | BL9: =IF(AND(BD9=1,N9>N8,ISNUMBER(BH9),ISNUMBER(BK9)),IF(AND(BE9>BH9,BF9<BI9,BK9>=p_GapMin,BK9<=p_GapMax),1,0),0) -> 0 | BM9: =IF(AND(BL9=1,E9>BI9),1,0) -> 0 | BN9: =IF(BL9=1,IF(BE9>=BH9*0.5,1,0),0) -> 0 | BO9: =IF(V9>MIN(OFFSET(V9,-MIN(p_FiLb-1,ROW()-5),0,MIN(p_FiLb-1,ROW()-5),1)),1,0) -> 1 | BP9: =IF(COUNTIF(OFFSET(V9,1-MIN(100,ROW()-4),0,MIN(100,ROW()-4),1),"<0")>=5,AVERAGEIF(OFFSET(V9,1-MIN(100,ROW()-4),0,MIN(100,ROW()-4),1),"<0"),"") | BQ9: =IF(ISNUMBER(BP9),IF(AND(V9<5*BP9,V9>V8,E9<AJ9),1,0),0) -> 0 | BR9: =AVERAGE(OFFSET(F9,1-MIN(5,ROW()-4),0,MIN(5,ROW()-4),1)) -> 3503440 | BS9: =IFERROR(IF(MATCH(G9,周线!$A$5:$A$84,0)<=1,"",INDEX(周线!$R$5:$R$84,MATCH(G9,周线!$A$5:$A$84,0)-1)),"") -> 0 | BT9: =IFERROR(IF(MATCH(G9,周线!$A$5:$A$84,0)<=1,"",INDEX(周线!$S$5:$S$84,MATCH(G9,周线!$A$5:$A$84,0)-1)),"") -> 0 | BU9: =IFERROR(IF(MATCH(G9,周线!$A$5:$A$84,0)<=1,"",INDEX(周线!$U$5:$U$84,MATCH(G9,周线!$A$5:$A$84,0)-1)),"") -> 0 | BV9: =IF(AND(BS9=1,S9<>-1,V9<0,BO9=1,E9<=H9,E9>=AJ9),1,0) -> 0 | BW9: =BL9 -> 0 | BX9: =BQ9 -> 0 | BY9: =IF(BS9=1,10,0)+IF(BU9=1,5,IF(BU9=-1,0,3))+IF(BT9=1,5,0)+IF(AND(AE9>AF9,AH9>AH8),5,0) -> 3 | BZ9: =IF(AND(E9<=H9,E9>=I9),10,IF(AND(E9>=AJ9,E9<I9),6,0))+IF(AND(V9<0,BO9=1),8,0)+IF(AT9<30,7,IF(AT9<50,3,0)) -> 21 | CA9: =IF(AND(BV9=1,BW9=1),25,IF(BW9=1,22,IF(BV9=1,15,IF(BX9=1,12,0)))) -> 0 | CB9: =IF(W9>0,6,0)+IF(F9<BR9,4,0) -> 4 | CC9: =IF(BC9>=3,15,IF(BC9>=p_RRmin,10,IF(BC9>=1.5,4,0))) -> 15 | CD9: =BY9+BZ9+CA9+CB9+CC9 -> 43 | CE9: =IF(AND(BS9<>1,BW9+BX9=0),1,0) -> 1 | CF9: =IF(BU9=-1,1,0) -> 0 | CG9: =IF(S9=-1,1,0) -> 1 | CH9: =IF(BV9+BW9+BX9=0,1,0) -> 1 | CI9: =IF(BC9<p_RRmin,1,0) -> 0 | CJ9: =IF(SUM(CE9:CI9)=0,IF(CD9>=p_GradeA,"A",IF(CD9>=p_GradeB,"B","C")),IF(AND(CI9=1,SUM(CE9:CH9)=0,CD9>=p_GradeB),"B","C")) -> C
A10: 45666 | B10: 19.51 | C10: 19.77 | D10: 19.42 | E10: 19.68 | F10: 4598500 | G10: =A10-WEEKDAY(A10,3) -> 45663 | H10: =2/(p_EmaF+1)*E10+(1-2/(p_EmaF+1))*H9 -> 19.772115 | I10: =2/(p_EmaS+1)*E10+(1-2/(p_EmaS+1))*I9 -> 19.796631 | J10: =2/(p_MacdF+1)*E10+(1-2/(p_MacdF+1))*J9 -> 19.768108 | K10: =2/(p_MacdS+1)*E10+(1-2/(p_MacdS+1))*K9 -> 19.796631 | L10: =J10-K10 -> -0.028523288 | M10: =2/(p_MacdSig+1)*L10+(1-2/(p_MacdSig+1))*M9 -> -0.0051104837 | N10: =L10-M10 -> -0.023412804 | O10: =IF(H10>H9,1,0) -> 0 | P10: =IF(H10<H9,1,0) -> 1 | Q10: =IF(N10>N9,1,0) -> 0 | R10: =IF(N10<N9,1,0) -> 1 | S10: =IF(AND(O10=1,Q10=1),1,IF(AND(P10=1,R10=1),-1,0)) -> -1 | T10: =IF(S10=1,"绿",IF(S10=-1,"红","蓝")) -> 红 | U10: =F10*(E10-E9) -> 689775 | V10: =2/(p_FiS+1)*U10+(1-2/(p_FiS+1))*V9 -> 303770.72 | W10: =2/(p_FiL+1)*U10+(1-2/(p_FiL+1))*W9 -> -45898.47 | X10: =MAX(C10-D10,ABS(C10-E9),ABS(D10-E9)) -> 0.35 | Y10: =AVERAGE(OFFSET(X10,1-MIN(p_AtrN,ROW()-4),0,MIN(p_AtrN,ROW()-4),1)) -> 0.37833333 | Z10: =IF(AND(C10-C9>D9-D10,C10-C9>0),C10-C9,0) -> 0.08 | AA10: =IF(AND(D9-D10>C10-C9,D9-D10>0),D9-D10,0) -> 0 | AB10: =2/(p_AdxN+1)*X10+(1-2/(p_AdxN+1))*AB9 -> 0.33900458 | AC10: =2/(p_AdxN+1)*Z10+(1-2/(p_AdxN+1))*AC9 -> 0.037517701 | AD10: =2/(p_AdxN+1)*AA10+(1-2/(p_AdxN+1))*AD9 -> 0.035685131 | AE10: =100*AC10/AB10 -> 11.067019 | AF10: =100*AD10/AB10 -> 10.526445 | AG10: =IFERROR(100*ABS(AE10-AF10)/(AE10+AF10),0) -> 2.5034137 | AH10: =2/(p_AdxN+1)*AG10+(1-2/(p_AdxN+1))*AH9 -> 19.400779 | AI10: =I10*(1+p_ChPct) -> 20.984429 | AJ10: =I10*(1-p_ChPct) -> 18.608833 | AK10: =I10+1*Y10 -> 20.174964 | AL10: =I10+2*Y10 -> 20.553298 | AM10: =I10+3*Y10 -> 20.931631 | AN10: =I10-1*Y10 -> 19.418298 | AO10: =I10-2*Y10 -> 19.039964 | AP10: =I10-3*Y10 -> 18.661631 | AQ10: =MAX(OFFSET(C10,1-MIN(p_StochN,ROW()-4),0,MIN(p_StochN,ROW()-4),1)) -> 20.26 | AR10: =MIN(OFFSET(D10,1-MIN(p_StochN,ROW()-4),0,MIN(p_StochN,ROW()-4),1)) -> 19.42 | AS10: =IF(AQ10=AR10,50,100*(E10-AR10)/(AQ10-AR10)) -> 30.952381 | AT10: =AVERAGE(OFFSET(AS10,1-MIN(p_StochSm,ROW()-4),0,MIN(p_StochSm,ROW()-4),1)) -> 22.374847 | AU10: =AVERAGE(OFFSET(AT10,1-MIN(p_StochSm,ROW()-4),0,MIN(p_StochSm,ROW()-4),1)) -> 31.199488 | AV10: =MAX(0,H10-D10) -> 0.35211519 | AW10: =IF(COUNTIF(OFFSET(AV10,1-MIN(p_PenLb,ROW()-4),0,MIN(p_PenLb,ROW()-4),1),">0")>0,SUM(OFFSET(AV10,1-MIN(p_PenLb,ROW()-4),0,MIN(p_PenLb,ROW()-4),1))/COUNTIF(OFFSET(AV10,1-MIN(p_PenLb,ROW()-4),0,MIN(p_PenLb,ROW()-4),1),">0"),0.5*Y10) -> 0.23288481 | AX10: =2*H10-H9 -> 19.756763 | AY10: =ROUND(MAX(AX10-AW10,0.01),2) -> 19.52 | AZ10: =IF(MIN(p_StopLb,ROW()-4)<2,D10,SMALL(OFFSET(D10,1-MIN(p_StopLb,ROW()-4),0,MIN(p_StopLb,ROW()-4),1),2)) -> 19.42 | BA10: =IF(MOD(ROUND(ROUNDDOWN(MIN(AZ10-0.01,AY10-p_StopAtr*Y10),2)*100,0),50)=0,ROUNDDOWN(MIN(AZ10-0.01,AY10-p_StopAtr*Y10),2)-0.01,ROUNDDOWN(MIN(AZ10-0.01,AY10-p_StopAtr*Y10),2)) -> 19.14 | BB10: =ROUND(AI10,2) -> 20.98 | BC10: =IF(AY10-BA10>0,(BB10-AY10)/(AY10-BA10),0) -> 3.8421053 | BD10: =IF(N10<0,1,0) -> 1 | BE10: =IF(AND(BD10=1,BD9=0),N10,IF(BD10=1,MIN(BE9,N10),BE9)) -> -0.023412804 | BF10: =IF(AND(BD10=1,BD9=0),D10,IF(BD10=1,MIN(BF9,D10),BF9)) -> 19.42 | BG10: =IF(AND(BD10=1,BD9=0),ROW(),IF(BD10=1,IF(N10<BE9,ROW(),BG9),BG9)) -> 10 | BH10: =IF(AND(BD10=1,BD9=0),BE9,BH9) | BI10: =IF(AND(BD10=1,BD9=0),BF9,BI9) | BJ10: =IF(AND(BD10=1,BD9=0),BG9,BJ9) | BK10: =IF(AND(ISNUMBER(BG10),ISNUMBER(BJ10)),BG10-BJ10,"") | BL10: =IF(AND(BD10=1,N10>N9,ISNUMBER(BH10),ISNUMBER(BK10)),IF(AND(BE10>BH10,BF10<BI10,BK10>=p_GapMin,BK10<=p_GapMax),1,0),0) -> 0 | BM10: =IF(AND(BL10=1,E10>BI10),1,0) -> 0 | BN10: =IF(BL10=1,IF(BE10>=BH10*0.5,1,0),0) -> 0 | BO10: =IF(V10>MIN(OFFSET(V10,-MIN(p_FiLb-1,ROW()-5),0,MIN(p_FiLb-1,ROW()-5),1)),1,0) -> 1 | BP10: =IF(COUNTIF(OFFSET(V10,1-MIN(100,ROW()-4),0,MIN(100,ROW()-4),1),"<0")>=5,AVERAGEIF(OFFSET(V10,1-MIN(100,ROW()-4),0,MIN(100,ROW()-4),1),"<0"),"") | BQ10: =IF(ISNUMBER(BP10),IF(AND(V10<5*BP10,V10>V9,E10<AJ10),1,0),0) -> 0 | BR10: =AVERAGE(OFFSET(F10,1-MIN(5,ROW()-4),0,MIN(5,ROW()-4),1)) -> 3576880 | BS10: =IFERROR(IF(MATCH(G10,周线!$A$5:$A$84,0)<=1,"",INDEX(周线!$R$5:$R$84,MATCH(G10,周线!$A$5:$A$84,0)-1)),"") -> 0 | BT10: =IFERROR(IF(MATCH(G10,周线!$A$5:$A$84,0)<=1,"",INDEX(周线!$S$5:$S$84,MATCH(G10,周线!$A$5:$A$84,0)-1)),"") -> 0 | BU10: =IFERROR(IF(MATCH(G10,周线!$A$5:$A$84,0)<=1,"",INDEX(周线!$U$5:$U$84,MATCH(G10,周线!$A$5:$A$84,0)-1)),"") -> 0 | BV10: =IF(AND(BS10=1,S10<>-1,V10<0,BO10=1,E10<=H10,E10>=AJ10),1,0) -> 0 | BW10: =BL10 -> 0 | BX10: =BQ10 -> 0 | BY10: =IF(BS10=1,10,0)+IF(BU10=1,5,IF(BU10=-1,0,3))+IF(BT10=1,5,0)+IF(AND(AE10>AF10,AH10>AH9),5,0) -> 3 | BZ10: =IF(AND(E10<=H10,E10>=I10),10,IF(AND(E10>=AJ10,E10<I10),6,0))+IF(AND(V10<0,BO10=1),8,0)+IF(AT10<30,7,IF(AT10<50,3,0)) -> 13 | CA10: =IF(AND(BV10=1,BW10=1),25,IF(BW10=1,22,IF(BV10=1,15,IF(BX10=1,12,0)))) -> 0 | CB10: =IF(W10>0,6,0)+IF(F10<BR10,4,0) -> 0 | CC10: =IF(BC10>=3,15,IF(BC10>=p_RRmin,10,IF(BC10>=1.5,4,0))) -> 15 | CD10: =BY10+BZ10+CA10+CB10+CC10 -> 31 | CE10: =IF(AND(BS10<>1,BW10+BX10=0),1,0) -> 1 | CF10: =IF(BU10=-1,1,0) -> 0 | CG10: =IF(S10=-1,1,0) -> 1 | CH10: =IF(BV10+BW10+BX10=0,1,0) -> 1 | CI10: =IF(BC10<p_RRmin,1,0) -> 0 | CJ10: =IF(SUM(CE10:CI10)=0,IF(CD10>=p_GradeA,"A",IF(CD10>=p_GradeB,"B","C")),IF(AND(CI10=1,SUM(CE10:CH10)=0,CD10>=p_GradeB),"B","C")) -> C
A11: 45667 | B11: 19.73 | C11: 19.92 | D11: 19.62 | E11: 19.83 | F11: 3373900 | G11: =A11-WEEKDAY(A11,3) -> 45663 | H11: =2/(p_EmaF+1)*E11+(1-2/(p_EmaF+1))*H10 -> 19.780384 | I11: =2/(p_EmaS+1)*E11+(1-2/(p_EmaS+1))*I10 -> 19.799103 | J11: =2/(p_MacdF+1)*E11+(1-2/(p_MacdF+1))*J10 -> 19.77763 | K11: =2/(p_MacdS+1)*E11+(1-2/(p_MacdS+1))*K10 -> 19.799103 | L11: =J11-K11 -> -0.021473176 | M11: =2/(p_MacdSig+1)*L11+(1-2/(p_MacdSig+1))*M10 -> -0.0083830221 | N11: =L11-M11 -> -0.013090154 | O11: =IF(H11>H10,1,0) -> 1 | P11: =IF(H11<H10,1,0) -> 0 | Q11: =IF(N11>N10,1,0) -> 1 | R11: =IF(N11<N10,1,0) -> 0 | S11: =IF(AND(O11=1,Q11=1),1,IF(AND(P11=1,R11=1),-1,0)) -> 1 | T11: =IF(S11=1,"绿",IF(S11=-1,"红","蓝")) -> 绿 | U11: =F11*(E11-E10) -> 506085 | V11: =2/(p_FiS+1)*U11+(1-2/(p_FiS+1))*V10 -> 438646.91 | W11: =2/(p_FiL+1)*U11+(1-2/(p_FiL+1))*W10 -> 32956.311 | X11: =MAX(C11-D11,ABS(C11-E10),ABS(D11-E10)) -> 0.3 | Y11: =AVERAGE(OFFSET(X11,1-MIN(p_AtrN,ROW()-4),0,MIN(p_AtrN,ROW()-4),1)) -> 0.36714286 | Z11: =IF(AND(C11-C10>D10-D11,C11-C10>0),C11-C10,0) -> 0.15 | AA11: =IF(AND(D10-D11>C11-C10,D10-D11>0),D10-D11,0) -> 0 | AB11: =2/(p_AdxN+1)*X11+(1-2/(p_AdxN+1))*AB10 -> 0.3334325 | AC11: =2/(p_AdxN+1)*Z11+(1-2/(p_AdxN+1))*AC10 -> 0.053586601 | AD11: =2/(p_AdxN+1)*AA11+(1-2/(p_AdxN+1))*AD10 -> 0.030587255 | AE11: =100*AC11/AB11 -> 16.071199 | AF11: =100*AD11/AB11 -> 9.1734475 | AG11: =IFERROR(100*ABS(AE11-AF11)/(AE11+AF11),0) -> 27.323621 | AH11: =2/(p_AdxN+1)*AG11+(1-2/(p_AdxN+1))*AH10 -> 20.532613 | AI11: =I11*(1+p_ChPct) -> 20.987049 | AJ11: =I11*(1-p_ChPct) -> 18.611157 | AK11: =I11+1*Y11 -> 20.166246 | AL11: =I11+2*Y11 -> 20.533389 | AM11: =I11+3*Y11 -> 20.900531 | AN11: =I11-1*Y11 -> 19.43196 | AO11: =I11-2*Y11 -> 19.064817 | AP11: =I11-3*Y11 -> 18.697674 | AQ11: =MAX(OFFSET(C11,1-MIN(p_StochN,ROW()-4),0,MIN(p_StochN,ROW()-4),1)) -> 20.26 | AR11: =MIN(OFFSET(D11,1-MIN(p_StochN,ROW()-4),0,MIN(p_StochN,ROW()-4),1)) -> 19.42 | AS11: =IF(AQ11=AR11,50,100*(E11-AR11)/(AQ11-AR11)) -> 48.809524 | AT11: =AVERAGE(OFFSET(AS11,1-MIN(p_StochSm,ROW()-4),0,MIN(p_StochSm,ROW()-4),1)) -> 30.952381 | AU11: =AVERAGE(OFFSET(AT11,1-MIN(p_StochSm,ROW()-4),0,MIN(p_StochSm,ROW()-4),1)) -> 25.498575 | AV11: =MAX(0,H11-D11) -> 0.16038445 | AW11: =IF(COUNTIF(OFFSET(AV11,1-MIN(p_PenLb,ROW()-4),0,MIN(p_PenLb,ROW()-4),1),">0")>0,SUM(OFFSET(AV11,1-MIN(p_PenLb,ROW()-4),0,MIN(p_PenLb,ROW()-4),1))/COUNTIF(OFFSET(AV11,1-MIN(p_PenLb,ROW()-4),0,MIN(p_PenLb,ROW()-4),1),">0"),0.5*Y11) -> 0.22252762 | AX11: =2*H11-H10 -> 19.788654 | AY11: =ROUND(MAX(AX11-AW11,0.01),2) -> 19.57 | AZ11: =IF(MIN(p_StopLb,ROW()-4)<2,D11,SMALL(OFFSET(D11,1-MIN(p_StopLb,ROW()-4),0,MIN(p_StopLb,ROW()-4),1),2)) -> 19.42 | BA11: =IF(MOD(ROUND(ROUNDDOWN(MIN(AZ11-0.01,AY11-p_StopAtr*Y11),2)*100,0),50)=0,ROUNDDOWN(MIN(AZ11-0.01,AY11-p_StopAtr*Y11),2)-0.01,ROUNDDOWN(MIN(AZ11-0.01,AY11-p_StopAtr*Y11),2)) -> 19.2 | BB11: =ROUND(AI11,2) -> 20.99 | BC11: =IF(AY11-BA11>0,(BB11-AY11)/(AY11-BA11),0) -> 3.8378378 | BD11: =IF(N11<0,1,0) -> 1 | BE11: =IF(AND(BD11=1,BD10=0),N11,IF(BD11=1,MIN(BE10,N11),BE10)) -> -0.023412804 | BF11: =IF(AND(BD11=1,BD10=0),D11,IF(BD11=1,MIN(BF10,D11),BF10)) -> 19.42 | BG11: =IF(AND(BD11=1,BD10=0),ROW(),IF(BD11=1,IF(N11<BE10,ROW(),BG10),BG10)) -> 10 | BH11: =IF(AND(BD11=1,BD10=0),BE10,BH10) | BI11: =IF(AND(BD11=1,BD10=0),BF10,BI10) | BJ11: =IF(AND(BD11=1,BD10=0),BG10,BJ10) | BK11: =IF(AND(ISNUMBER(BG11),ISNUMBER(BJ11)),BG11-BJ11,"") | BL11: =IF(AND(BD11=1,N11>N10,ISNUMBER(BH11),ISNUMBER(BK11)),IF(AND(BE11>BH11,BF11<BI11,BK11>=p_GapMin,BK11<=p_GapMax),1,0),0) -> 0 | BM11: =IF(AND(BL11=1,E11>BI11),1,0) -> 0 | BN11: =IF(BL11=1,IF(BE11>=BH11*0.5,1,0),0) -> 0 | BO11: =IF(V11>MIN(OFFSET(V11,-MIN(p_FiLb-1,ROW()-5),0,MIN(p_FiLb-1,ROW()-5),1)),1,0) -> 1 | BP11: =IF(COUNTIF(OFFSET(V11,1-MIN(100,ROW()-4),0,MIN(100,ROW()-4),1),"<0")>=5,AVERAGEIF(OFFSET(V11,1-MIN(100,ROW()-4),0,MIN(100,ROW()-4),1),"<0"),"") | BQ11: =IF(ISNUMBER(BP11),IF(AND(V11<5*BP11,V11>V10,E11<AJ11),1,0),0) -> 0 | BR11: =AVERAGE(OFFSET(F11,1-MIN(5,ROW()-4),0,MIN(5,ROW()-4),1)) -> 3687240 | BS11: =IFERROR(IF(MATCH(G11,周线!$A$5:$A$84,0)<=1,"",INDEX(周线!$R$5:$R$84,MATCH(G11,周线!$A$5:$A$84,0)-1)),"") -> 0 | BT11: =IFERROR(IF(MATCH(G11,周线!$A$5:$A$84,0)<=1,"",INDEX(周线!$S$5:$S$84,MATCH(G11,周线!$A$5:$A$84,0)-1)),"") -> 0 | BU11: =IFERROR(IF(MATCH(G11,周线!$A$5:$A$84,0)<=1,"",INDEX(周线!$U$5:$U$84,MATCH(G11,周线!$A$5:$A$84,0)-1)),"") -> 0 | BV11: =IF(AND(BS11=1,S11<>-1,V11<0,BO11=1,E11<=H11,E11>=AJ11),1,0) -> 0 | BW11: =BL11 -> 0 | BX11: =BQ11 -> 0 | BY11: =IF(BS11=1,10,0)+IF(BU11=1,5,IF(BU11=-1,0,3))+IF(BT11=1,5,0)+IF(AND(AE11>AF11,AH11>AH10),5,0) -> 8 | BZ11: =IF(AND(E11<=H11,E11>=I11),10,IF(AND(E11>=AJ11,E11<I11),6,0))+IF(AND(V11<0,BO11=1),8,0)+IF(AT11<30,7,IF(AT11<50,3,0)) -> 3 | CA11: =IF(AND(BV11=1,BW11=1),25,IF(BW11=1,22,IF(BV11=1,15,IF(BX11=1,12,0)))) -> 0 | CB11: =IF(W11>0,6,0)+IF(F11<BR11,4,0) -> 10 | CC11: =IF(BC11>=3,15,IF(BC11>=p_RRmin,10,IF(BC11>=1.5,4,0))) -> 15 | CD11: =BY11+BZ11+CA11+CB11+CC11 -> 36 | CE11: =IF(AND(BS11<>1,BW11+BX11=0),1,0) -> 1 | CF11: =IF(BU11=-1,1,0) -> 0 | CG11: =IF(S11=-1,1,0) -> 0 | CH11: =IF(BV11+BW11+BX11=0,1,0) -> 1 | CI11: =IF(BC11<p_RRmin,1,0) -> 0 | CJ11: =IF(SUM(CE11:CI11)=0,IF(CD11>=p_GradeA,"A",IF(CD11>=p_GradeB,"B","C")),IF(AND(CI11=1,SUM(CE11:CH11)=0,CD11>=p_GradeB),"B","C")) -> C
A12: 45670 | B12: 19.9 | C12: 20 | D12: 19.87 | E12: 19.97 | F12: 3313700 | G12: =A12-WEEKDAY(A12,3) -> 45670 | H12: =2/(p_EmaF+1)*E12+(1-2/(p_EmaF+1))*H11 -> 19.807472 | I12: =2/(p_EmaS+1)*E12+(1-2/(p_EmaS+1))*I11 -> 19.811762 | J12: =2/(p_MacdF+1)*E12+(1-2/(p_MacdF+1))*J11 -> 19.807225 | K12: =2/(p_MacdS+1)*E12+(1-2/(p_MacdS+1))*K11 -> 19.811762 | L12: =J12-K12 -> -0.0045367843 | M12: =2/(p_MacdSig+1)*L12+(1-2/(p_MacdSig+1))*M11 -> -0.0076137746 | N12: =L12-M12 -> 0.0030769903 | O12: =IF(H12>H11,1,0) -> 1 | P12: =IF(H12<H11,1,0) -> 0 | Q12: =IF(N12>N11,1,0) -> 1 | R12: =IF(N12<N11,1,0) -> 0 | S12: =IF(AND(O12=1,Q12=1),1,IF(AND(P12=1,R12=1),-1,0)) -> 1 | T12: =IF(S12=1,"绿",IF(S12=-1,"红","蓝")) -> 绿 | U12: =F12*(E12-E11) -> 463918 | V12: =2/(p_FiS+1)*U12+(1-2/(p_FiS+1))*V11 -> 455494.3 | W12: =2/(p_FiL+1)*U12+(1-2/(p_FiL+1))*W11 -> 94522.267 | X12: =MAX(C12-D12,ABS(C12-E11),ABS(D12-E11)) -> 0.17 | Y12: =AVERAGE(OFFSET(X12,1-MIN(p_AtrN,ROW()-4),0,MIN(p_AtrN,ROW()-4),1)) -> 0.3425 | Z12: =IF(AND(C12-C11>D11-D12,C12-C11>0),C12-C11,0) -> 0.08 | AA12: =IF(AND(D11-D12>C12-C11,D11-D12>0),D11-D12,0) -> 0 | AB12: =2/(p_AdxN+1)*X12+(1-2/(p_AdxN+1))*AB11 -> 0.310085 | AC12: =2/(p_AdxN+1)*Z12+(1-2/(p_AdxN+1))*AC11 -> 0.057359944 | AD12: =2/(p_AdxN+1)*AA12+(1-2/(p_AdxN+1))*AD11 -> 0.026217647 | AE12: =100*AC12/AB12 -> 18.498136 | AF12: =100*AD12/AB12 -> 8.4549874 | AG12: =IFERROR(100*ABS(AE12-AF12)/(AE12+AF12),0) -> 37.261538 | AH12: =2/(p_AdxN+1)*AG12+(1-2/(p_AdxN+1))*AH11 -> 22.92246 | AI12: =I12*(1+p_ChPct) -> 21.000468 | AJ12: =I12*(1-p_ChPct) -> 18.623056 | AK12: =I12+1*Y12 -> 20.154262 | AL12: =I12+2*Y12 -> 20.496762 | AM12: =I12+3*Y12 -> 20.839262 | AN12: =I12-1*Y12 -> 19.469262 | AO12: =I12-2*Y12 -> 19.126762 | AP12: =I12-3*Y12 -> 18.784262 | AQ12: =MAX(OFFSET(C12,1-MIN(p_StochN,ROW()-4),0,MIN(p_StochN,ROW()-4),1)) -> 20 | AR12: =MIN(OFFSET(D12,1-MIN(p_StochN,ROW()-4),0,MIN(p_StochN,ROW()-4),1)) -> 19.42 | AS12: =IF(AQ12=AR12,50,100*(E12-AR12)/(AQ12-AR12)) -> 94.827586 | AT12: =AVERAGE(OFFSET(AS12,1-MIN(p_StochSm,ROW()-4),0,MIN(p_StochSm,ROW()-4),1)) -> 58.196497 | AU12: =AVERAGE(OFFSET(AT12,1-MIN(p_StochSm,ROW()-4),0,MIN(p_StochSm,ROW()-4),1)) -> 37.174575 | AV12: =MAX(0,H12-D12) -> 0 | AW12: =IF(COUNTIF(OFFSET(AV12,1-MIN(p_PenLb,ROW()-4),0,MIN(p_PenLb,ROW()-4),1),">0")>0,SUM(OFFSET(AV12,1-MIN(p_PenLb,ROW()-4),0,MIN(p_PenLb,ROW()-4),1))/COUNTIF(OFFSET(AV12,1-MIN(p_PenLb,ROW()-4),0,MIN(p_PenLb,ROW()-4),1),">0"),0.5*Y12) -> 0.22252762 | AX12: =2*H12-H11 -> 19.83456 | AY12: =ROUND(MAX(AX12-AW12,0.01),2) -> 19.61 | AZ12: =IF(MIN(p_StopLb,ROW()-4)<2,D12,SMALL(OFFSET(D12,1-MIN(p_StopLb,ROW()-4),0,MIN(p_StopLb,ROW()-4),1),2)) -> 19.42 | BA12: =IF(MOD(ROUND(ROUNDDOWN(MIN(AZ12-0.01,AY12-p_StopAtr*Y12),2)*100,0),50)=0,ROUNDDOWN(MIN(AZ12-0.01,AY12-p_StopAtr*Y12),2)-0.01,ROUNDDOWN(MIN(AZ12-0.01,AY12-p_StopAtr*Y12),2)) -> 19.26 | BB12: =ROUND(AI12,2) -> 21 | BC12: =IF(AY12-BA12>0,(BB12-AY12)/(AY12-BA12),0) -> 3.9714286 | BD12: =IF(N12<0,1,0) -> 0 | BE12: =IF(AND(BD12=1,BD11=0),N12,IF(BD12=1,MIN(BE11,N12),BE11)) -> -0.023412804 | BF12: =IF(AND(BD12=1,BD11=0),D12,IF(BD12=1,MIN(BF11,D12),BF11)) -> 19.42 | BG12: =IF(AND(BD12=1,BD11=0),ROW(),IF(BD12=1,IF(N12<BE11,ROW(),BG11),BG11)) -> 10 | BH12: =IF(AND(BD12=1,BD11=0),BE11,BH11) | BI12: =IF(AND(BD12=1,BD11=0),BF11,BI11) | BJ12: =IF(AND(BD12=1,BD11=0),BG11,BJ11) | BK12: =IF(AND(ISNUMBER(BG12),ISNUMBER(BJ12)),BG12-BJ12,"") | BL12: =IF(AND(BD12=1,N12>N11,ISNUMBER(BH12),ISNUMBER(BK12)),IF(AND(BE12>BH12,BF12<BI12,BK12>=p_GapMin,BK12<=p_GapMax),1,0),0) -> 0 | BM12: =IF(AND(BL12=1,E12>BI12),1,0) -> 0 | BN12: =IF(BL12=1,IF(BE12>=BH12*0.5,1,0),0) -> 0 | BO12: =IF(V12>MIN(OFFSET(V12,-MIN(p_FiLb-1,ROW()-5),0,MIN(p_FiLb-1,ROW()-5),1)),1,0) -> 1 | BP12: =IF(COUNTIF(OFFSET(V12,1-MIN(100,ROW()-4),0,MIN(100,ROW()-4),1),"<0")>=5,AVERAGEIF(OFFSET(V12,1-MIN(100,ROW()-4),0,MIN(100,ROW()-4),1),"<0"),"") | BQ12: =IF(ISNUMBER(BP12),IF(AND(V12<5*BP12,V12>V11,E12<AJ12),1,0),0) -> 0 | BR12: =AVERAGE(OFFSET(F12,1-MIN(5,ROW()-4),0,MIN(5,ROW()-4),1)) -> 3581100 | BS12: =IFERROR(IF(MATCH(G12,周线!$A$5:$A$84,0)<=1,"",INDEX(周线!$R$5:$R$84,MATCH(G12,周线!$A$5:$A$84,0)-1)),"") -> 0 | BT12: =IFERROR(IF(MATCH(G12,周线!$A$5:$A$84,0)<=1,"",INDEX(周线!$S$5:$S$84,MATCH(G12,周线!$A$5:$A$84,0)-1)),"") -> 0 | BU12: =IFERROR(IF(MATCH(G12,周线!$A$5:$A$84,0)<=1,"",INDEX(周线!$U$5:$U$84,MATCH(G12,周线!$A$5:$A$84,0)-1)),"") -> -1 | BV12: =IF(AND(BS12=1,S12<>-1,V12<0,BO12=1,E12<=H12,E12>=AJ12),1,0) -> 0 | BW12: =BL12 -> 0 | BX12: =BQ12 -> 0 | BY12: =IF(BS12=1,10,0)+IF(BU12=1,5,IF(BU12=-1,0,3))+IF(BT12=1,5,0)+IF(AND(AE12>AF12,AH12>AH11),5,0) -> 5 | BZ12: =IF(AND(E12<=H12,E12>=I12),10,IF(AND(E12>=AJ12,E12<I12),6,0))+IF(AND(V12<0,BO12=1),8,0)+IF(AT12<30,7,IF(AT12<50,3,0)) -> 0 | CA12: =IF(AND(BV12=1,BW12=1),25,IF(BW12=1,22,IF(BV12=1,15,IF(BX12=1,12,0)))) -> 0 | CB12: =IF(W12>0,6,0)+IF(F12<BR12,4,0) -> 10 | CC12: =IF(BC12>=3,15,IF(BC12>=p_RRmin,10,IF(BC12>=1.5,4,0))) -> 15 | CD12: =BY12+BZ12+CA12+CB12+CC12 -> 30 | CE12: =IF(AND(BS12<>1,BW12+BX12=0),1,0) -> 1 | CF12: =IF(BU12=-1,1,0) -> 1 | CG12: =IF(S12=-1,1,0) -> 0 | CH12: =IF(BV12+BW12+BX12=0,1,0) -> 1 | CI12: =IF(BC12<p_RRmin,1,0) -> 0 | CJ12: =IF(SUM(CE12:CI12)=0,IF(CD12>=p_GradeA,"A",IF(CD12>=p_GradeB,"B","C")),IF(AND(CI12=1,SUM(CE12:CH12)=0,CD12>=p_GradeB),"B","C")) -> C
A13: 45671 | B13: 20.03 | C13: 20.15 | D13: 19.98 | E13: 20.11 | F13: 2717800 | G13: =A13-WEEKDAY(A13,3) -> 45670 | H13: =2/(p_EmaF+1)*E13+(1-2/(p_EmaF+1))*H12 -> 19.850691 | I13: =2/(p_EmaS+1)*E13+(1-2/(p_EmaS+1))*I12 -> 19.833854 | J13: =2/(p_MacdF+1)*E13+(1-2/(p_MacdF+1))*J12 -> 19.853806 | K13: =2/(p_MacdS+1)*E13+(1-2/(p_MacdS+1))*K12 -> 19.833854 | L13: =J13-K13 -> 0.019952261 | M13: =2/(p_MacdSig+1)*L13+(1-2/(p_MacdSig+1))*M12 -> -0.0021005675 | N13: =L13-M13 -> 0.022052828 | O13: =IF(H13>H12,1,0) -> 1 | P13: =IF(H13<H12,1,0) -> 0 | Q13: =IF(N13>N12,1,0) -> 1 | R13: =IF(N13<N12,1,0) -> 0 | S13: =IF(AND(O13=1,Q13=1),1,IF(AND(P13=1,R13=1),-1,0)) -> 1 | T13: =IF(S13=1,"绿",IF(S13=-1,"红","蓝")) -> 绿 | U13: =F13*(E13-E12) -> 380492 | V13: =2/(p_FiS+1)*U13+(1-2/(p_FiS+1))*V12 -> 405492.77 | W13: =2/(p_FiL+1)*U13+(1-2/(p_FiL+1))*W12 -> 135375.09 | X13: =MAX(C13-D13,ABS(C13-E12),ABS(D13-E12)) -> 0.18 | Y13: =AVERAGE(OFFSET(X13,1-MIN(p_AtrN,ROW()-4),0,MIN(p_AtrN,ROW()-4),1)) -> 0.32444444 | Z13: =IF(AND(C13-C12>D12-D13,C13-C12>0),C13-C12,0) -> 0.15 | AA13: =IF(AND(D12-D13>C13-C12,D12-D13>0),D12-D13,0) -> 0 | AB13: =2/(p_AdxN+1)*X13+(1-2/(p_AdxN+1))*AB12 -> 0.29150143 | AC13: =2/(p_AdxN+1)*Z13+(1-2/(p_AdxN+1))*AC12 -> 0.070594237 | AD13: =2/(p_AdxN+1)*AA13+(1-2/(p_AdxN+1))*AD12 -> 0.022472269 | AE13: =100*AC13/AB13 -> 24.217459 | AF13: =100*AD13/AB13 -> 7.7091455 | AG13: =IFERROR(100*ABS(AE13-AF13)/(AE13+AF13),0) -> 51.707075 | AH13: =2/(p_AdxN+1)*AG13+(1-2/(p_AdxN+1))*AH12 -> 27.034548 | AI13: =I13*(1+p_ChPct) -> 21.023885 | AJ13: =I13*(1-p_ChPct) -> 18.643822 | AK13: =I13+1*Y13 -> 20.158298 | AL13: =I13+2*Y13 -> 20.482742 | AM13: =I13+3*Y13 -> 20.807187 | AN13: =I13-1*Y13 -> 19.509409 | AO13: =I13-2*Y13 -> 19.184965 | AP13: =I13-3*Y13 -> 18.86052 | AQ13: =MAX(OFFSET(C13,1-MIN(p_StochN,ROW()-4),0,MIN(p_StochN,ROW()-4),1)) -> 20.15 | AR13: =MIN(OFFSET(D13,1-MIN(p_StochN,ROW()-4),0,MIN(p_StochN,ROW()-4),1)) -> 19.42 | AS13: =IF(AQ13=AR13,50,100*(E13-AR13)/(AQ13-AR13)) -> 94.520548 | AT13: =AVERAGE(OFFSET(AS13,1-MIN(p_StochSm,ROW()-4),0,MIN(p_StochSm,ROW()-4),1)) -> 79.385886 | AU13: =AVERAGE(OFFSET(AT13,1-MIN(p_StochSm,ROW()-4),0,MIN(p_StochSm,ROW()-4),1)) -> 56.178255 | AV13: =MAX(0,H13-D13) -> 0 | AW13: =IF(COUNTIF(OFFSET(AV13,1-MIN(p_PenLb,ROW()-4),0,MIN(p_PenLb,ROW()-4),1),">0")>0,SUM(OFFSET(AV13,1-MIN(p_PenLb,ROW()-4),0,MIN(p_PenLb,ROW()-4),1))/COUNTIF(OFFSET(AV13,1-MIN(p_PenLb,ROW()-4),0,MIN(p_PenLb,ROW()-4),1),">0"),0.5*Y13) -> 0.22252762 | AX13: =2*H13-H12 -> 19.893909 | AY13: =ROUND(MAX(AX13-AW13,0.01),2) -> 19.67 | AZ13: =IF(MIN(p_StopLb,ROW()-4)<2,D13,SMALL(OFFSET(D13,1-MIN(p_StopLb,ROW()-4),0,MIN(p_StopLb,ROW()-4),1),2)) -> 19.42 | BA13: =IF(MOD(ROUND(ROUNDDOWN(MIN(AZ13-0.01,AY13-p_StopAtr*Y13),2)*100,0),50)=0,ROUNDDOWN(MIN(AZ13-0.01,AY13-p_StopAtr*Y13),2)-0.01,ROUNDDOWN(MIN(AZ13-0.01,AY13-p_StopAtr*Y13),2)) -> 19.34 | BB13: =ROUND(AI13,2) -> 21.02 | BC13: =IF(AY13-BA13>0,(BB13-AY13)/(AY13-BA13),0) -> 4.0909091 | BD13: =IF(N13<0,1,0) -> 0 | BE13: =IF(AND(BD13=1,BD12=0),N13,IF(BD13=1,MIN(BE12,N13),BE12)) -> -0.023412804 | BF13: =IF(AND(BD13=1,BD12=0),D13,IF(BD13=1,MIN(BF12,D13),BF12)) -> 19.42 | BG13: =IF(AND(BD13=1,BD12=0),ROW(),IF(BD13=1,IF(N13<BE12,ROW(),BG12),BG12)) -> 10 | BH13: =IF(AND(BD13=1,BD12=0),BE12,BH12) | BI13: =IF(AND(BD13=1,BD12=0),BF12,BI12) | BJ13: =IF(AND(BD13=1,BD12=0),BG12,BJ12) | BK13: =IF(AND(ISNUMBER(BG13),ISNUMBER(BJ13)),BG13-BJ13,"") | BL13: =IF(AND(BD13=1,N13>N12,ISNUMBER(BH13),ISNUMBER(BK13)),IF(AND(BE13>BH13,BF13<BI13,BK13>=p_GapMin,BK13<=p_GapMax),1,0),0) -> 0 | BM13: =IF(AND(BL13=1,E13>BI13),1,0) -> 0 | BN13: =IF(BL13=1,IF(BE13>=BH13*0.5,1,0),0) -> 0 | BO13: =IF(V13>MIN(OFFSET(V13,-MIN(p_FiLb-1,ROW()-5),0,MIN(p_FiLb-1,ROW()-5),1)),1,0) -> 1 | BP13: =IF(COUNTIF(OFFSET(V13,1-MIN(100,ROW()-4),0,MIN(100,ROW()-4),1),"<0")>=5,AVERAGEIF(OFFSET(V13,1-MIN(100,ROW()-4),0,MIN(100,ROW()-4),1),"<0"),"") | BQ13: =IF(ISNUMBER(BP13),IF(AND(V13<5*BP13,V13>V12,E13<AJ13),1,0),0) -> 0 | BR13: =AVERAGE(OFFSET(F13,1-MIN(5,ROW()-4),0,MIN(5,ROW()-4),1)) -> 3404060 | BS13: =IFERROR(IF(MATCH(G13,周线!$A$5:$A$84,0)<=1,"",INDEX(周线!$R$5:$R$84,MATCH(G13,周线!$A$5:$A$84,0)-1)),"") -> 0 | BT13: =IFERROR(IF(MATCH(G13,周线!$A$5:$A$84,0)<=1,"",INDEX(周线!$S$5:$S$84,MATCH(G13,周线!$A$5:$A$84,0)-1)),"") -> 0 | BU13: =IFERROR(IF(MATCH(G13,周线!$A$5:$A$84,0)<=1,"",INDEX(周线!$U$5:$U$84,MATCH(G13,周线!$A$5:$A$84,0)-1)),"") -> -1 | BV13: =IF(AND(BS13=1,S13<>-1,V13<0,BO13=1,E13<=H13,E13>=AJ13),1,0) -> 0 | BW13: =BL13 -> 0 | BX13: =BQ13 -> 0 | BY13: =IF(BS13=1,10,0)+IF(BU13=1,5,IF(BU13=-1,0,3))+IF(BT13=1,5,0)+IF(AND(AE13>AF13,AH13>AH12),5,0) -> 5 | BZ13: =IF(AND(E13<=H13,E13>=I13),10,IF(AND(E13>=AJ13,E13<I13),6,0))+IF(AND(V13<0,BO13=1),8,0)+IF(AT13<30,7,IF(AT13<50,3,0)) -> 0 | CA13: =IF(AND(BV13=1,BW13=1),25,IF(BW13=1,22,IF(BV13=1,15,IF(BX13=1,12,0)))) -> 0 | CB13: =IF(W13>0,6,0)+IF(F13<BR13,4,0) -> 10 | CC13: =IF(BC13>=3,15,IF(BC13>=p_RRmin,10,IF(BC13>=1.5,4,0))) -> 15 | CD13: =BY13+BZ13+CA13+CB13+CC13 -> 30 | CE13: =IF(AND(BS13<>1,BW13+BX13=0),1,0) -> 1 | CF13: =IF(BU13=-1,1,0) -> 1 | CG13: =IF(S13=-1,1,0) -> 0 | CH13: =IF(BV13+BW13+BX13=0,1,0) -> 1 | CI13: =IF(BC13<p_RRmin,1,0) -> 0 | CJ13: =IF(SUM(CE13:CI13)=0,IF(CD13>=p_GradeA,"A",IF(CD13>=p_GradeB,"B","C")),IF(AND(CI13=1,SUM(CE13:CH13)=0,CD13>=p_GradeB),"B","C")) -> C
A14: 45672 | B14: 20.17 | C14: 20.21 | D14: 19.77 | E14: 19.81 | F14: 5357200 | G14: =A14-WEEKDAY(A14,3) -> 45670 | H14: =2/(p_EmaF+1)*E14+(1-2/(p_EmaF+1))*H13 -> 19.844878 | I14: =2/(p_EmaS+1)*E14+(1-2/(p_EmaS+1))*I13 -> 19.832087 | J14: =2/(p_MacdF+1)*E14+(1-2/(p_MacdF+1))*J13 -> 19.847066 | K14: =2/(p_MacdS+1)*E14+(1-2/(p_MacdS+1))*K13 -> 19.832087 | L14: =J14-K14 -> 0.014979835 | M14: =2/(p_MacdSig+1)*L14+(1-2/(p_MacdSig+1))*M13 -> 0.0013155129 | N14: =L14-M14 -> 0.013664322 | O14: =IF(H14>H13,1,0) -> 0 | P14: =IF(H14<H13,1,0) -> 1 | Q14: =IF(N14>N13,1,0) -> 0 | R14: =IF(N14<N13,1,0) -> 1 | S14: =IF(AND(O14=1,Q14=1),1,IF(AND(P14=1,R14=1),-1,0)) -> -1 | T14: =IF(S14=1,"绿",IF(S14=-1,"红","蓝")) -> 红 | U14: =F14*(E14-E13) -> -1607160 | V14: =2/(p_FiS+1)*U14+(1-2/(p_FiS+1))*V13 -> -936275.74 | W14: =2/(p_FiL+1)*U14+(1-2/(p_FiL+1))*W13 -> -113558.5 | X14: =MAX(C14-D14,ABS(C14-E13),ABS(D14-E13)) -> 0.44 | Y14: =AVERAGE(OFFSET(X14,1-MIN(p_AtrN,ROW()-4),0,MIN(p_AtrN,ROW()-4),1)) -> 0.336 | Z14: =IF(AND(C14-C13>D13-D14,C14-C13>0),C14-C13,0) -> 0 | AA14: =IF(AND(D13-D14>C14-C13,D13-D14>0),D13-D14,0) -> 0.21 | AB14: =2/(p_AdxN+1)*X14+(1-2/(p_AdxN+1))*AB13 -> 0.31271551 | AC14: =2/(p_AdxN+1)*Z14+(1-2/(p_AdxN+1))*AC13 -> 0.060509346 | AD14: =2/(p_AdxN+1)*AA14+(1-2/(p_AdxN+1))*AD13 -> 0.049261945 | AE14: =100*AC14/AB14 -> 19.349647 | AF14: =100*AD14/AB14 -> 15.752959 | AG14: =IFERROR(100*ABS(AE14-AF14)/(AE14+AF14),0) -> 10.246214 | AH14: =2/(p_AdxN+1)*AG14+(1-2/(p_AdxN+1))*AH13 -> 24.636214 | AI14: =I14*(1+p_ChPct) -> 21.022012 | AJ14: =I14*(1-p_ChPct) -> 18.642161 | AK14: =I14+1*Y14 -> 20.168087 | AL14: =I14+2*Y14 -> 20.504087 | AM14: =I14+3*Y14 -> 20.840087 | AN14: =I14-1*Y14 -> 19.496087 | AO14: =I14-2*Y14 -> 19.160087 | AP14: =I14-3*Y14 -> 18.824087 | AQ14: =MAX(OFFSET(C14,1-MIN(p_StochN,ROW()-4),0,MIN(p_StochN,ROW()-4),1)) -> 20.21 | AR14: =MIN(OFFSET(D14,1-MIN(p_StochN,ROW()-4),0,MIN(p_StochN,ROW()-4),1)) -> 19.42 | AS14: =IF(AQ14=AR14,50,100*(E14-AR14)/(AQ14-AR14)) -> 49.367089 | AT14: =AVERAGE(OFFSET(AS14,1-MIN(p_StochSm,ROW()-4),0,MIN(p_StochSm,ROW()-4),1)) -> 79.571741 | AU14: =AVERAGE(OFFSET(AT14,1-MIN(p_StochSm,ROW()-4),0,MIN(p_StochSm,ROW()-4),1)) -> 72.384708 | AV14: =MAX(0,H14-D14) -> 0.07487767 | AW14: =IF(COUNTIF(OFFSET(AV14,1-MIN(p_PenLb,ROW()-4),0,MIN(p_PenLb,ROW()-4),1),">0")>0,SUM(OFFSET(AV14,1-MIN(p_PenLb,ROW()-4),0,MIN(p_PenLb,ROW()-4),1))/COUNTIF(OFFSET(AV14,1-MIN(p_PenLb,ROW()-4),0,MIN(p_PenLb,ROW()-4),1),">0"),0.5*Y14) -> 0.20407137 | AX14: =2*H14-H13 -> 19.839065 | AY14: =ROUND(MAX(AX14-AW14,0.01),2) -> 19.63 | AZ14: =IF(MIN(p_StopLb,ROW()-4)<2,D14,SMALL(OFFSET(D14,1-MIN(p_StopLb,ROW()-4),0,MIN(p_StopLb,ROW()-4),1),2)) -> 19.42 | BA14: =IF(MOD(ROUND(ROUNDDOWN(MIN(AZ14-0.01,AY14-p_StopAtr*Y14),2)*100,0),50)=0,ROUNDDOWN(MIN(AZ14-0.01,AY14-p_StopAtr*Y14),2)-0.01,ROUNDDOWN(MIN(AZ14-0.01,AY14-p_StopAtr*Y14),2)) -> 19.29 | BB14: =ROUND(AI14,2) -> 21.02 | BC14: =IF(AY14-BA14>0,(BB14-AY14)/(AY14-BA14),0) -> 4.0882353 | BD14: =IF(N14<0,1,0) -> 0 | BE14: =IF(AND(BD14=1,BD13=0),N14,IF(BD14=1,MIN(BE13,N14),BE13)) -> -0.023412804 | BF14: =IF(AND(BD14=1,BD13=0),D14,IF(BD14=1,MIN(BF13,D14),BF13)) -> 19.42 | BG14: =IF(AND(BD14=1,BD13=0),ROW(),IF(BD14=1,IF(N14<BE13,ROW(),BG13),BG13)) -> 10 | BH14: =IF(AND(BD14=1,BD13=0),BE13,BH13) | BI14: =IF(AND(BD14=1,BD13=0),BF13,BI13) | BJ14: =IF(AND(BD14=1,BD13=0),BG13,BJ13) | BK14: =IF(AND(ISNUMBER(BG14),ISNUMBER(BJ14)),BG14-BJ14,"") | BL14: =IF(AND(BD14=1,N14>N13,ISNUMBER(BH14),ISNUMBER(BK14)),IF(AND(BE14>BH14,BF14<BI14,BK14>=p_GapMin,BK14<=p_GapMax),1,0),0) -> 0 | BM14: =IF(AND(BL14=1,E14>BI14),1,0) -> 0 | BN14: =IF(BL14=1,IF(BE14>=BH14*0.5,1,0),0) -> 0 | BO14: =IF(V14>MIN(OFFSET(V14,-MIN(p_FiLb-1,ROW()-5),0,MIN(p_FiLb-1,ROW()-5),1)),1,0) -> 0 | BP14: =IF(COUNTIF(OFFSET(V14,1-MIN(100,ROW()-4),0,MIN(100,ROW()-4),1),"<0")>=5,AVERAGEIF(OFFSET(V14,1-MIN(100,ROW()-4),0,MIN(100,ROW()-4),1),"<0"),"") | BQ14: =IF(ISNUMBER(BP14),IF(AND(V14<5*BP14,V14>V13,E14<AJ14),1,0),0) -> 0 | BR14: =AVERAGE(OFFSET(F14,1-MIN(5,ROW()-4),0,MIN(5,ROW()-4),1)) -> 3872220 | BS14: =IFERROR(IF(MATCH(G14,周线!$A$5:$A$84,0)<=1,"",INDEX(周线!$R$5:$R$84,MATCH(G14,周线!$A$5:$A$84,0)-1)),"") -> 0 | BT14: =IFERROR(IF(MATCH(G14,周线!$A$5:$A$84,0)<=1,"",INDEX(周线!$S$5:$S$84,MATCH(G14,周线!$A$5:$A$84,0)-1)),"") -> 0 | BU14: =IFERROR(IF(MATCH(G14,周线!$A$5:$A$84,0)<=1,"",INDEX(周线!$U$5:$U$84,MATCH(G14,周线!$A$5:$A$84,0)-1)),"") -> -1 | BV14: =IF(AND(BS14=1,S14<>-1,V14<0,BO14=1,E14<=H14,E14>=AJ14),1,0) -> 0 | BW14: =BL14 -> 0 | BX14: =BQ14 -> 0 | BY14: =IF(BS14=1,10,0)+IF(BU14=1,5,IF(BU14=-1,0,3))+IF(BT14=1,5,0)+IF(AND(AE14>AF14,AH14>AH13),5,0) -> 0 | BZ14: =IF(AND(E14<=H14,E14>=I14),10,IF(AND(E14>=AJ14,E14<I14),6,0))+IF(AND(V14<0,BO14=1),8,0)+IF(AT14<30,7,IF(AT14<50,3,0)) -> 6 | CA14: =IF(AND(BV14=1,BW14=1),25,IF(BW14=1,22,IF(BV14=1,15,IF(BX14=1,12,0)))) -> 0 | CB14: =IF(W14>0,6,0)+IF(F14<BR14,4,0) -> 0 | CC14: =IF(BC14>=3,15,IF(BC14>=p_RRmin,10,IF(BC14>=1.5,4,0))) -> 15 | CD14: =BY14+BZ14+CA14+CB14+CC14 -> 21 | CE14: =IF(AND(BS14<>1,BW14+BX14=0),1,0) -> 1 | CF14: =IF(BU14=-1,1,0) -> 1 | CG14: =IF(S14=-1,1,0) -> 1 | CH14: =IF(BV14+BW14+BX14=0,1,0) -> 1 | CI14: =IF(BC14<p_RRmin,1,0) -> 0 | CJ14: =IF(SUM(CE14:CI14)=0,IF(CD14>=p_GradeA,"A",IF(CD14>=p_GradeB,"B","C")),IF(AND(CI14=1,SUM(CE14:CH14)=0,CD14>=p_GradeB),"B","C")) -> C
